Workbook

Sheet Instrucciones
A1: QUINIELA MUNDIAL 2026 — Cómo llenar tu pronóstico
A3: Fecha límite: 11 de junio de 2026, antes del primer partido.
A5: 1) Hoja GRUPOS — pon el marcador (goles) de los 72 partidos de la fase de grupos.
A6: Solo escribes goles en las celdas amarillas; los equipos ya están fijos.
A7: La tabla de la derecha de cada grupo se ordena sola con los desempates oficiales FIFA.
A9: 2) Hoja ELIMINATORIAS — tu cuadro se arma solo desde tus grupos (1º, 2º y los 8 mejores terceros).
A10: Elige el GANADOR de cada llave en la lista desplegable. La ronda siguiente se llena con tus ganadores.
A11: Aquí no se ponen goles, solo quién avanza, hasta el campeón.
A13: 3) Hoja ESPECIALES — el campeón sale solo de tu cuadro. Completa goleador, primer eliminado y sorpresa.
A15: CÓMO SE PUNTÚA (máximo 718 puntos):
A16: • Grupos (50%): marcador exacto 5 · solo diferencia 3 · solo resultado (1X2) 2. Te quedas con el más alto.
A17: • Avance KO (35%): por cada equipo tuyo que llega a la ronda — R32 2 · R16 4 · Cuartos 6 · Semis 10 · Final 16.
... A21: Devuelve este mismo archivo lleno. ¡Suerte!

Sheet Grupos
A1: QUINIELA MUNDIAL 2026 — Pronóstico
A2: Jugador: | D2: Fecha límite: 11-jun-2026 (antes del 1er partido)
A3: Pon el marcador (goles) de los 72 partidos. Las celdas amarillas son tu input. La tabla de la derecha se ordena sola.
A5: GRUPO A | H5: # | I5: Equipo | J5: Pts | K5: DG | L5: GF
B6: Fecha | C6: Local | F6: Visita
B7: 06-11 | C7: México | F7: Sudáfrica | H7: 1 | I7: =IFERROR(VLOOKUP(INDEX(_calc!$B$2:$B$5,MATCH(1,_calc!$L$2:$L$5,0)),_eq!$A:$B,2,FALSE),"") | J7: =IFERROR(INDEX(_calc!$D$2:$D$5,MATCH(1,_calc!$L$2:$L$5,0)),"") | K7: =IFERROR(INDEX(_calc!$G$2:$G$5,MATCH(1,_calc!$L$2:$L$5,0)),"") | L7: =IFERROR(INDEX(_calc!$E$2:$E$5,MATCH(1,_calc!$L$2:$L$5,0)),"")
B8: 06-11 | C8: Corea del Sur | F8: Chequia | H8: 2 | I8: =IFERROR(VLOOKUP(INDEX(_calc!$B$2:$B$5,MATCH(2,_calc!$L$2:$L$5,0)),_eq!$A:$B,2,FALSE),"") | J8: =IFERROR(INDEX(_calc!$D$2:$D$5,MATCH(2,_calc!$L$2:$L$5,0)),"") | K8: =IFERROR(INDEX(_calc!$G$2:$G$5,MATCH(2,_calc!$L$2:$L$5,0)),"") | L8: =IFERROR(INDEX(_calc!$E$2:$E$5,MATCH(2,_calc!$L$2:$L$5,0)),"")
B9: 06-18 | C9: Chequia | F9: Sudáfrica | H9: 3 | I9: =IFERROR(VLOOKUP(INDEX(_calc!$B$2:$B$5,MATCH(3,_calc!$L$2:$L$5,0)),_eq!$A:$B,2,FALSE),"") | J9: =IFERROR(INDEX(_calc!$D$2:$D$5,MATCH(3,_calc!$L$2:$L$5,0)),"") | K9: =IFERROR(INDEX(_calc!$G$2:$G$5,MATCH(3,_calc!$L$2:$L$5,0)),"") | L9: =IFERROR(INDEX(_calc!$E$2:$E$5,MATCH(3,_calc!$L$2:$L$5,0)),"")
B10: 06-18 | C10: México | F10: Corea del Sur | H10: 4 | I10: =IFERROR(VLOOKUP(INDEX(_calc!$B$2:$B$5,MATCH(4,_calc!$L$2:$L$5,0)),_eq!$A:$B,2,FALSE),"") | J10: =IFERROR(INDEX(_calc!$D$2:$D$5,MATCH(4,_calc!$L$2:$L$5,0)),"") | K10: =IFERROR(INDEX(_calc!$G$2:$G$5,MATCH(4,_calc!$L$2:$L$5,0)),"") | L10: =IFERROR(INDEX(_calc!$E$2:$E$5,MATCH(4,_calc!$L$2:$L$5,0)),"")
B11: 06-24 | C11: Chequia | F11: México
B12: 06-24 | C12: Sudáfrica | F12: Corea del Sur
A14: GRUPO B | H14: # | I14: Equipo | J14: Pts | K14: DG | L14: GF
B15: Fecha | C15: Local | F15: Visita
B16: 06-12 | C16: Canadá | F16: Bosnia y Herzegovina | H16: 1 | I16: =IFERROR(VLOOKUP(INDEX(_calc!$B$6:$B$9,MATCH(1,_calc!$L$6:$L$9,0)),_eq!$A:$B,2,FALSE),"") | J16: =IFERROR(INDEX(_calc!$D$6:$D$9,MATCH(1,_calc!$L$6:$L$9,0)),"") | K16: =IFERROR(INDEX(_calc!$G$6:$G$9,MATCH(1,_calc!$L$6:$L$9,0)),"") | L16: =IFERROR(INDEX(_calc!$E$6:$E$9,MATCH(1,_calc!$L$6:$L$9,0)),"")
B17: 06-13 | C17: Catar | F17: Suiza | H17: 2 | I17: =IFERROR(VLOOKUP(INDEX(_calc!$B$6:$B$9,MATCH(2,_calc!$L$6:$L$9,0)),_eq!$A:$B,2,FALSE),"") | J17: =IFERROR(INDEX(_calc!$D$6:$D$9,MATCH(2,_calc!$L$6:$L$9,0)),"") | K17: =IFERROR(INDEX(_calc!$G$6:$G$9,MATCH(2,_calc!$L$6:$L$9,0)),"") | L17: =IFERROR(INDEX(_calc!$E$6:$E$9,MATCH(2,_calc!$L$6:$L$9,0)),"")
B18: 06-18 | C18: Suiza | F18: Bosnia y Herzegovina | H18: 3 | I18: =IFERROR(VLOOKUP(INDEX(_calc!$B$6:$B$9,MATCH(3,_calc!$L$6:$L$9,0)),_eq!$A:$B,2,FALSE),"") | J18: =IFERROR(INDEX(_calc!$D$6:$D$9,MATCH(3,_calc!$L$6:$L$9,0)),"") | K18: =IFERROR(INDEX(_calc!$G$6:$G$9,MATCH(3,_calc!$L$6:$L$9,0)),"") | L18: =IFERROR(INDEX(_calc!$E$6:$E$9,MATCH(3,_calc!$L$6:$L$9,0)),"")
B19: 06-18 | C19: Canadá | F19: Catar | H19: 4 | I19: =IFERROR(VLOOKUP(INDEX(_calc!$B$6:$B$9,MATCH(4,_calc!$L$6:$L$9,0)),_eq!$A:$B,2,FALSE),"") | J19: =IFERROR(INDEX(_calc!$D$6:$D$9,MATCH(4,_calc!$L$6:$L$9,0)),"") | K19: =IFERROR(INDEX(_calc!$G$6:$G$9,MATCH(4,_calc!$L$6:$L$9,0)),"") | L19: =IFERROR(INDEX(_calc!$E$6:$E$9,MATCH(4,_calc!$L$6:$L$9,0)),"")
B20: 06-24 | C20: Suiza | F20: Canadá
B21: 06-24 | C21: Bosnia y Herzegovina | F21: Catar
A23: GRUPO C | H23: # | I23: Equipo | J23: Pts | K23: DG | L23: GF
B24: Fecha | C24: Local | F24: Visita
B25: 06-13 | C25: Brasil | F25: Marruecos | H25: 1 | I25: =IFERROR(VLOOKUP(INDEX(_calc!$B$10:$B$13,MATCH(1,_calc!$L$10:$L$13,0)),_eq!$A:$B,2,FALSE),"") | J25: =IFERROR(INDEX(_calc!$D$10:$D$13,MATCH(1,_calc!$L$10:$L$13,0)),"") | K25: =IFERROR(INDEX(_calc!$G$10:$G$13,MATCH(1,_calc!$L$10:$L$13,0)),"") | L25: =IFERROR(INDEX(_calc!$E$10:$E$13,MATCH(1,_calc!$L$10:$L$13,0)),"")
B26: 06-13 | C26: Haití | F26: Escocia | H26: 2 | I26: =IFERROR(VLOOKUP(INDEX(_calc!$B$10:$B$13,MATCH(2,_calc!$L$10:$L$13,0)),_eq!$A:$B,2,FALSE),"") | J26: =IFERROR(INDEX(_calc!$D$10:$D$13,MATCH(2,_calc!$L$10:$L$13,0)),"") | K26: =IFERROR(INDEX(_calc!$G$10:$G$13,MATCH(2,_calc!$L$10:$L$13,0)),"") | L26: =IFERROR(INDEX(_calc!$E$10:$E$13,MATCH(2,_calc!$L$10:$L$13,0)),"")
B27: 06-19 | C27: Escocia | F27: Marruecos | H27: 3 | I27: =IFERROR(VLOOKUP(INDEX(_calc!$B$10:$B$13,MATCH(3,_calc!$L$10:$L$13,0)),_eq!$A:$B,2,FALSE),"") | J27: =IFERROR(INDEX(_calc!$D$10:$D$13,MATCH(3,_calc!$L$10:$L$13,0)),"") | K27: =IFERROR(INDEX(_calc!$G$10:$G$13,MATCH(3,_calc!$L$10:$L$13,0)),"") | L27: =IFERROR(INDEX(_calc!$E$10:$E$13,MATCH(3,_calc!$L$10:$L$13,0)),"")
B28: 06-19 | C28: Brasil | F28: Haití | H28: 4 | I28: =IFERROR(VLOOKUP(INDEX(_calc!$B$10:$B$13,MATCH(4,_calc!$L$10:$L$13,0)),_eq!$A:$B,2,FALSE),"") | J28: =IFERROR(INDEX(_calc!$D$10:$D$13,MATCH(4,_calc!$L$10:$L$13,0)),"") | K28: =IFERROR(INDEX(_calc!$G$10:$G$13,MATCH(4,_calc!$L$10:$L$13,0)),"") | L28: =IFERROR(INDEX(_calc!$E$10:$E$13,MATCH(4,_calc!$L$10:$L$13,0)),"")
B29: 06-24 | C29: Escocia | F29: Brasil
B30: 06-24 | C30: Marruecos | F30: Haití
A32: GRUPO D | H32: # | I32: Equipo | J32: Pts | K32: DG | L32: GF
B33: Fecha | C33: Local | F33: Visita
B34: 06-12 | C34: Estados Unidos | F34: Paraguay | H34: 1 | I34: =IFERROR(VLOOKUP(INDEX(_calc!$B$14:$B$17,MATCH(1,_calc!$L$14:$L$17,0)),_eq!$A:$B,2,FALSE),"") | J34: =IFERROR(INDEX(_calc!$D$14:$D$17,MATCH(1,_calc!$L$14:$L$17,0)),"") | K34: =IFERROR(INDEX(_calc!$G$14:$G$17,MATCH(1,_calc!$L$14:$L$17,0)),"") | L34: =IFERROR(INDEX(_calc!$E$14:$E$17,MATCH(1,_calc!$L$14:$L$17,0)),"")
B35: 06-14 | C35: Australia | F35: Turquía | H35: 2 | I35: =IFERROR(VLOOKUP(INDEX(_calc!$B$14:$B$17,MATCH(2,_calc!$L$14:$L$17,0)),_eq!$A:$B,2,FALSE),"") | J35: =IFERROR(INDEX(_calc!$D$14:$D$17,MATCH(2,_calc!$L$14:$L$17,0)),"") | K35: =IFERROR(INDEX(_calc!$G$14:$G$17,MATCH(2,_calc!$L$14:$L$17,0)),"") | L35: =IFERROR(INDEX(_calc!$E$14:$E$17,MATCH(2,_calc!$L$14:$L$17,0)),"")
B36: 06-19 | C36: Estados Unidos | F36: Australia | H36: 3 | I36: =IFERROR(VLOOKUP(INDEX(_calc!$B$14:$B$17,MATCH(3,_calc!$L$14:$L$17,0)),_eq!$A:$B,2,FALSE),"") | J36: =IFERROR(INDEX(_calc!$D$14:$D$17,MATCH(3,_calc!$L$14:$L$17,0)),"") | K36: =IFERROR(INDEX(_calc!$G$14:$G$17,MATCH(3,_calc!$L$14:$L$17,0)),"") | L36: =IFERROR(INDEX(_calc!$E$14:$E$17,MATCH(3,_calc!$L$14:$L$17,0)),"")
B37: 06-19 | C37: Turquía | F37: Paraguay | H37: 4 | I37: =IFERROR(VLOOKUP(INDEX(_calc!$B$14:$B$17,MATCH(4,_calc!$L$14:$L$17,0)),_eq!$A:$B,2,FALSE),"") | J37: =IFERROR(INDEX(_calc!$D$14:$D$17,MATCH(4,_calc!$L$14:$L$17,0)),"") | K37: =IFERROR(INDEX(_calc!$G$14:$G$17,MATCH(4,_calc!$L$14:$L$17,0)),"") | L37: =IFERROR(INDEX(_calc!$E$14:$E$17,MATCH(4,_calc!$L$14:$L$17,0)),"")
B38: 06-25 | C38: Turquía | F38: Estados Unidos
B39: 06-25 | C39: Paraguay | F39: Australia
A41: GRUPO E | H41: # | I41: Equipo | J41: Pts | K41: DG | L41: GF
B42: Fecha | C42: Local | F42: Visita
B43: 06-14 | C43: Alemania | F43: Curazao | H43: 1 | I43: =IFERROR(VLOOKUP(INDEX(_calc!$B$18:$B$21,MATCH(1,_calc!$L$18:$L$21,0)),_eq!$A:$B,2,FALSE),"") | J43: =IFERROR(INDEX(_calc!$D$18:$D$21,MATCH(1,_calc!$L$18:$L$21,0)),"") | K43: =IFERROR(INDEX(_calc!$G$18:$G$21,MATCH(1,_calc!$L$18:$L$21,0)),"") | L43: =IFERROR(INDEX(_calc!$E$18:$E$21,MATCH(1,_calc!$L$18:$L$21,0)),"")
B44: 06-14 | C44: Costa de Marfil | F44: Ecuador | H44: 2 | I44: =IFERROR(VLOOKUP(INDEX(_calc!$B$18:$B$21,MATCH(2,_calc!$L$18:$L$21,0)),_eq!$A:$B,2,FALSE),"") | J44: =IFERROR(INDEX(_calc!$D$18:$D$21,MATCH(2,_calc!$L$18:$L$21,0)),"") | K44: =IFERROR(INDEX(_calc!$G$18:$G$21,MATCH(2,_calc!$L$18:$L$21,0)),"") | L44: =IFERROR(INDEX(_calc!$E$18:$E$21,MATCH(2,_calc!$L$18:$L$21,0)),"")
B45: 06-20 | C45: Alemania | F45: Costa de Marfil | H45: 3 | I45: =IFERROR(VLOOKUP(INDEX(_calc!$B$18:$B$21,MATCH(3,_calc!$L$18:$L$21,0)),_eq!$A:$B,2,FALSE),"") | J45: =IFERROR(INDEX(_calc!$D$18:$D$21,MATCH(3,_calc!$L$18:$L$21,0)),"") | K45: =IFERROR(INDEX(_calc!$G$18:$G$21,MATCH(3,_calc!$L$18:$L$21,0)),"") | L45: =IFERROR(INDEX(_calc!$E$18:$E$21,MATCH(3,_calc!$L$18:$L$21,0)),"")
...

Sheet Eliminatorias
A1: ELIMINATORIAS — pica quién avanza en cada llave
A2: Tu cuadro se arma solo desde tus grupos (1º/2º + 8 mejores terceros). Elige el GANADOR de cada llave; la siguiente ronda se llena con tus ganadores. Sin goles aquí.
A4: OCTAVOS DE FINAL (R32)
B5: # | C5: Local | E5: Visita | F5: GANADOR
B6: 73 | C6: =H6 | D6: vs | E6: =I6 | H6: =IFERROR(VLOOKUP(_calc!$B$80,_eq!$A:$B,2,FALSE),"") | I6: =IFERROR(VLOOKUP(_calc!$C$80,_eq!$A:$B,2,FALSE),"")
B7: 74 | C7: =H7 | D7: vs | E7: =I7 | H7: =IFERROR(VLOOKUP(_calc!$B$81,_eq!$A:$B,2,FALSE),"") | I7: =IFERROR(VLOOKUP(_calc!$C$81,_eq!$A:$B,2,FALSE),"")
B8: 75 | C8: =H8 | D8: vs | E8: =I8 | H8: =IFERROR(VLOOKUP(_calc!$B$82,_eq!$A:$B,2,FALSE),"") | I8: =IFERROR(VLOOKUP(_calc!$C$82,_eq!$A:$B,2,FALSE),"")
B9: 76 | C9: =H9 | D9: vs | E9: =I9 | H9: =IFERROR(VLOOKUP(_calc!$B$83,_eq!$A:$B,2,FALSE),"") | I9: =IFERROR(VLOOKUP(_calc!$C$83,_eq!$A:$B,2,FALSE),"")
B10: 77 | C10: =H10 | D10: vs | E10: =I10 | H10: =IFERROR(VLOOKUP(_calc!$B$84,_eq!$A:$B,2,FALSE),"") | I10: =IFERROR(VLOOKUP(_calc!$C$84,_eq!$A:$B,2,FALSE),"")
B11: 78 | C11: =H11 | D11: vs | E11: =I11 | H11: =IFERROR(VLOOKUP(_calc!$B$85,_eq!$A:$B,2,FALSE),"") | I11: =IFERROR(VLOOKUP(_calc!$C$85,_eq!$A:$B,2,FALSE),"")
B12: 79 | C12: =H12 | D12: vs | E12: =I12 | H12: =IFERROR(VLOOKUP(_calc!$B$86,_eq!$A:$B,2,FALSE),"") | I12: =IFERROR(VLOOKUP(_calc!$C$86,_eq!$A:$B,2,FALSE),"")
B13: 80 | C13: =H13 | D13: vs | E13: =I13 | H13: =IFERROR(VLOOKUP(_calc!$B$87,_eq!$A:$B,2,FALSE),"") | I13: =IFERROR(VLOOKUP(_calc!$C$87,_eq!$A:$B,2,FALSE),"")
B14: 81 | C14: =H14 | D14: vs | E14: =I14 | H14: =IFERROR(VLOOKUP(_calc!$B$88,_eq!$A:$B,2,FALSE),"") | I14: =IFERROR(VLOOKUP(_calc!$C$88,_eq!$A:$B,2,FALSE),"")
B15: 82 | C15: =H15 | D15: vs | E15: =I15 | H15: =IFERROR(VLOOKUP(_calc!$B$89,_eq!$A:$B,2,FALSE),"") | I15: =IFERROR(VLOOKUP(_calc!$C$89,_eq!$A:$B,2,FALSE),"")
B16: 83 | C16: =H16 | D16: vs | E16: =I16 | H16: =IFERROR(VLOOKUP(_calc!$B$90,_eq!$A:$B,2,FALSE),"") | I16: =IFERROR(VLOOKUP(_calc!$C$90,_eq!$A:$B,2,FALSE),"")
B17: 84 | C17: =H17 | D17: vs | E17: =I17 | H17: =IFERROR(VLOOKUP(_calc!$B$91,_eq!$A:$B,2,FALSE),"") | I17: =IFERROR(VLOOKUP(_calc!$C$91,_eq!$A:$B,2,FALSE),"")
B18: 85 | C18: =H18 | D18: vs | E18: =I18 | H18: =IFERROR(VLOOKUP(_calc!$B$92,_eq!$A:$B,2,FALSE),"") | I18: =IFERROR(VLOOKUP(_calc!$C$92,_eq!$A:$B,2,FALSE),"")
B19: 86 | C19: =H19 | D19: vs | E19: =I19 | H19: =IFERROR(VLOOKUP(_calc!$B$93,_eq!$A:$B,2,FALSE),"") | I19: =IFERROR(VLOOKUP(_calc!$C$93,_eq!$A:$B,2,FALSE),"")
B20: 87 | C20: =H20 | D20: vs | E20: =I20 | H20: =IFERROR(VLOOKUP(_calc!$B$94,_eq!$A:$B,2,FALSE),"") | I20: =IFERROR(VLOOKUP(_calc!$C$94,_eq!$A:$B,2,FALSE),"")
B21: 88 | C21: =H21 | D21: vs | E21: =I21 | H21: =IFERROR(VLOOKUP(_calc!$B$95,_eq!$A:$B,2,FALSE),"") | I21: =IFERROR(VLOOKUP(_calc!$C$95,_eq!$A:$B,2,FALSE),"")
A23: DIECISÉIS (R16)
B24: # | C24: Local | E24: Visita | F24: GANADOR
B25: 89 | C25: =H25 | D25: vs | E25: =I25 | H25: =F7 | I25: =F10
B26: 90 | C26: =H26 | D26: vs | E26: =I26 | H26: =F6 | I26: =F8
B27: 91 | C27: =H27 | D27: vs | E27: =I27 | H27: =F9 | I27: =F11
B28: 92 | C28: =H28 | D28: vs | E28: =I28 | H28: =F12 | I28: =F13
B29: 93 | C29: =H29 | D29: vs | E29: =I29 | H29: =F16 | I29: =F17
B30: 94 | C30: =H30 | D30: vs | E30: =I30 | H30: =F14 | I30: =F15
B31: 95 | C31: =H31 | D31: vs | E31: =I31 | H31: =F19 | I31: =F21
B32: 96 | C32: =H32 | D32: vs | E32: =I32 | H32: =F18 | I32: =F20
A34: CUARTOS
B35: # | C35: Local | E35: Visita | F35: GANADOR
B36: 97 | C36: =H36 | D36: vs | E36: =I36 | H36: =F25 | I36: =F26
B37: 98 | C37: =H37 | D37: vs | E37: =I37 | H37: =F29 | I37: =F30
B38: 99 | C38: =H38 | D38: vs | E38: =I38 | H38: =F27 | I38: =F28
B39: 100 | C39: =H39 | D39: vs | E39: =I39 | H39: =F31 | I39: =F32
A41: SEMIFINALES
B42: # | C42: Local | E42: Visita | F42: GANADOR
B43: 101 | C43: =H43 | D43: vs | E43: =I43 | H43: =F36 | I43: =F37
B44: 102 | C44: =H44 | D44: vs | E44: =I44 | H44: =F38 | I44: =F39
...

Sheet Especiales
A1: ESPECIALES DE TORNEO
A2: El campeón sale de tu cuadro (automático). Completa los demás.
A4: Campeón (auto) | B4: =IF(Eliminatorias!F52="","(elige la final)",Eliminatorias!F52)
A5: Subcampeón (auto) | B5: =IF(Eliminatorias!F52="","",IF(Eliminatorias!F52=Eliminatorias!H52,Eliminatorias!I52,Eliminatorias!H52))
A6: Goleador (Bota de Oro) | C6: (texto libre)
A7: Primer eliminado | C7: (elige de la lista)
A8: Sorpresa del torneo | C8: (texto libre)

Sheet _calc
A2: A | B2: MEX | C2: 1 | D2: =IF(AND(ISNUMBER(Grupos!D7),ISNUMBER(Grupos!E7)),IF(Grupos!D7>Grupos!E7,3,IF(Grupos!D7=Grupos!E7,1,0)),0)+IF(AND(ISNUMBER(Grupos!D10),ISNUMBER(Grupos!E10)),IF(Grupos!D10>Grupos!E10,3,IF(Grupos!D10=Grupos!E10,1,0)),0)+IF(AND(ISNUMBER(Grupos!E11),ISNUMBER(Grupos!D11)),IF(Grupos!E11>Grupos!D11,3,IF(Grupos!E11=Grupos!D11,1,0)),0) | E2: =IF(AND(ISNUMBER(Grupos!D7),ISNUMBER(Grupos!E7)),Grupos!D7,0)+IF(AND(ISNUMBER(Grupos!D10),ISNUMBER(Grupos!E10)),Grupos!D10,0)+IF(AND(ISNUMBER(Grupos!E11),ISNUMBER(Grupos!D11)),Grupos!E11,0) | F2: =IF(AND(ISNUMBER(Grupos!D7),ISNUMBER(Grupos!E7)),Grupos!E7,0)+IF(AND(ISNUMBER(Grupos!D10),ISNUMBER(Grupos!E10)),Grupos!E10,0)+IF(AND(ISNUMBER(Grupos!E11),ISNUMBER(Grupos!D11)),Grupos!D11,0) | G2: =E2-F2 | H2: =IF(AND(AND(ISNUMBER(Grupos!D7),ISNUMBER(Grupos!E7)),D3=D2),IF(Grupos!D7>Grupos!E7,3,IF(Grupos!D7=Grupos!E7,1,0)),0)+IF(AND(AND(ISNUMBER(Grupos!D10),ISNUMBER(Grupos!E10)),D4=D2),IF(Grupos!D10>Grupos!E10,3,IF(Grupos!D10=Grupos!E10,1,0)),0)+IF(AND(AND(ISNUMBER(Grupos!E11),ISNUMBER(Grupos!D11)),D5=D2),IF(Grupos!E11>Grupos!D11,3,IF(Grupos!E11=Grupos!D11,1,0)),0) | I2: =IF(AND(AND(ISNUMBER(Grupos!D7),ISNUMBER(Grupos!E7)),D3=D2),Grupos!D7-Grupos!E7,0)+IF(AND(AND(ISNUMBER(Grupos!D10),ISNUMBER(Grupos!E10)),D4=D2),Grupos!D10-Grupos!E10,0)+IF(AND(AND(ISNUMBER(Grupos!E11),ISNUMBER(Grupos!D11)),D5=D2),Grupos!E11-Grupos!D11,0) | J2: =IF(AND(AND(ISNUMBER(Grupos!D7),ISNUMBER(Grupos!E7)),D3=D2),Grupos!D7,0)+IF(AND(AND(ISNUMBER(Grupos!D10),ISNUMBER(Grupos!E10)),D4=D2),Grupos!D10,0)+IF(AND(AND(ISNUMBER(Grupos!E11),ISNUMBER(Grupos!D11)),D5=D2),Grupos!E11,0) | K2: =D2*100000000000+H2*1000000000+(I2+50)*10000000+J2*100000+(G2+50)*1000+E2*10+(4-C2) | L2: =RANK(K2,K2:K5,0) | N2: =INDEX(B2:B5,MATCH(1,L2:L5,0)) | O2: =INDEX(B2:B5,MATCH(2,L2:L5,0)) | P2: =INDEX(B2:B5,MATCH(3,L2:L5,0))
A3: A | B3: RSA | C3: 2 | D3: =IF(AND(ISNUMBER(Grupos!E7),ISNUMBER(Grupos!D7)),IF(Grupos!E7>Grupos!D7,3,IF(Grupos!E7=Grupos!D7,1,0)),0)+IF(AND(ISNUMBER(Grupos!E9),ISNUMBER(Grupos!D9)),IF(Grupos!E9>Grupos!D9,3,IF(Grupos!E9=Grupos!D9,1,0)),0)+IF(AND(ISNUMBER(Grupos!D12),ISNUMBER(Grupos!E12)),IF(Grupos!D12>Grupos!E12,3,IF(Grupos!D12=Grupos!E12,1,0)),0) | E3: =IF(AND(ISNUMBER(Grupos!E7),ISNUMBER(Grupos!D7)),Grupos!E7,0)+IF(AND(ISNUMBER(Grupos!E9),ISNUMBER(Grupos!D9)),Grupos!E9,0)+IF(AND(ISNUMBER(Grupos!D12),ISNUMBER(Grupos!E12)),Grupos!D12,0) | F3: =IF(AND(ISNUMBER(Grupos!E7),ISNUMBER(Grupos!D7)),Grupos!D7,0)+IF(AND(ISNUMBER(Grupos!E9),ISNUMBER(Grupos!D9)),Grupos!D9,0)+IF(AND(ISNUMBER(Grupos!D12),ISNUMBER(Grupos!E12)),Grupos!E12,0) | G3: =E3-F3 | H3: =IF(AND(AND(ISNUMBER(Grupos!E7),ISNUMBER(Grupos!D7)),D2=D3),IF(Grupos!E7>Grupos!D7,3,IF(Grupos!E7=Grupos!D7,1,0)),0)+IF(AND(AND(ISNUMBER(Grupos!E9),ISNUMBER(Grupos!D9)),D5=D3),IF(Grupos!E9>Grupos!D9,3,IF(Grupos!E9=Grupos!D9,1,0)),0)+IF(AND(AND(ISNUMBER(Grupos!D12),ISNUMBER(Grupos!E12)),D4=D3),IF(Grupos!D12>Grupos!E12,3,IF(Grupos!D12=Grupos!E12,1,0)),0) | I3: =IF(AND(AND(ISNUMBER(Grupos!E7),ISNUMBER(Grupos!D7)),D2=D3),Grupos!E7-Grupos!D7,0)+IF(AND(AND(ISNUMBER(Grupos!E9),ISNUMBER(Grupos!D9)),D5=D3),Grupos!E9-Grupos!D9,0)+IF(AND(AND(ISNUMBER(Grupos!D12),ISNUMBER(Grupos!E12)),D4=D3),Grupos!D12-Grupos!E12,0) | J3: =IF(AND(AND(ISNUMBER(Grupos!E7),ISNUMBER(Grupos!D7)),D2=D3),Grupos!E7,0)+IF(AND(AND(ISNUMBER(Grupos!E9),ISNUMBER(Grupos!D9)),D5=D3),Grupos!E9,0)+IF(AND(AND(ISNUMBER(Grupos!D12),ISNUMBER(Grupos!E12)),D4=D3),Grupos!D12,0) | K3: =D3*100000000000+H3*1000000000+(I3+50)*10000000+J3*100000+(G3+50)*1000+E3*10+(4-C3) | L3: =RANK(K3,K2:K5,0)
A4: A | B4: KOR | C4: 3 | D4: =IF(AND(ISNUMBER(Grupos!D8),ISNUMBER(Grupos!E8)),IF(Grupos!D8>Grupos!E8,3,IF(Grupos!D8=Grupos!E8,1,0)),0)+IF(AND(ISNUMBER(Grupos!E10),ISNUMBER(Grupos!D10)),IF(Grupos!E10>Grupos!D10,3,IF(Grupos!E10=Grupos!D10,1,0)),0)+IF(AND(ISNUMBER(Grupos!E12),ISNUMBER(Grupos!D12)),IF(Grupos!E12>Grupos!D12,3,IF(Grupos!E12=Grupos!D12,1,0)),0) | E4: =IF(AND(ISNUMBER(Grupos!D8),ISNUMBER(Grupos!E8)),Grupos!D8,0)+IF(AND(ISNUMBER(Grupos!E10),ISNUMBER(Grupos!D10)),Grupos!E10,0)+IF(AND(ISNUMBER(Grupos!E12),ISNUMBER(Grupos!D12)),Grupos!E12,0) | F4: =IF(AND(ISNUMBER(Grupos!D8),ISNUMBER(Grupos!E8)),Grupos!E8,0)+IF(AND(ISNUMBER(Grupos!E10),ISNUMBER(Grupos!D10)),Grupos!D10,0)+IF(AND(ISNUMBER(Grupos!E12),ISNUMBER(Grupos!D12)),Grupos!D12,0) | G4: =E4-F4 | H4: =IF(AND(AND(ISNUMBER(Grupos!D8),ISNUMBER(Grupos!E8)),D5=D4),IF(Grupos!D8>Grupos!E8,3,IF(Grupos!D8=Grupos!E8,1,0)),0)+IF(AND(AND(ISNUMBER(Grupos!E10),ISNUMBER(Grupos!D10)),D2=D4),IF(Grupos!E10>Grupos!D10,3,IF(Grupos!E10=Grupos!D10,1,0)),0)+IF(AND(AND(ISNUMBER(Grupos!E12),ISNUMBER(Grupos!D12)),D3=D4),IF(Grupos!E12>Grupos!D12,3,IF(Grupos!E12=Grupos!D12,1,0)),0) | I4: =IF(AND(AND(ISNUMBER(Grupos!D8),ISNUMBER(Grupos!E8)),D5=D4),Grupos!D8-Grupos!E8,0)+IF(AND(AND(ISNUMBER(Grupos!E10),ISNUMBER(Grupos!D10)),D2=D4),Grupos!E10-Grupos!D10,0)+IF(AND(AND(ISNUMBER(Grupos!E12),ISNUMBER(Grupos!D12)),D3=D4),Grupos!E12-Grupos!D12,0) | J4: =IF(AND(AND(ISNUMBER(Grupos!D8),ISNUMBER(Grupos!E8)),D5=D4),Grupos!D8,0)+IF(AND(AND(ISNUMBER(Grupos!E10),ISNUMBER(Grupos!D10)),D2=D4),Grupos!E10,0)+IF(AND(AND(ISNUMBER(Grupos!E12),ISNUMBER(Grupos!D12)),D3=D4),Grupos!E12,0) | K4: =D4*100000000000+H4*1000000000+(I4+50)*10000000+J4*100000+(G4+50)*1000+E4*10+(4-C4) | L4: =RANK(K4,K2:K5,0)
A5: A | B5: CZE | C5: 4 | D5: =IF(AND(ISNUMBER(Grupos!E8),ISNUMBER(Grupos!D8)),IF(Grupos!E8>Grupos!D8,3,IF(Grupos!E8=Grupos!D8,1,0)),0)+IF(AND(ISNUMBER(Grupos!D9),ISNUMBER(Grupos!E9)),IF(Grupos!D9>Grupos!E9,3,IF(Grupos!D9=Grupos!E9,1,0)),0)+IF(AND(ISNUMBER(Grupos!D11),ISNUMBER(Grupos!E11)),IF(Grupos!D11>Grupos!E11,3,IF(Grupos!D11=Grupos!E11,1,0)),0) | E5: =IF(AND(ISNUMBER(Grupos!E8),ISNUMBER(Grupos!D8)),Grupos!E8,0)+IF(AND(ISNUMBER(Grupos!D9),ISNUMBER(Grupos!E9)),Grupos!D9,0)+IF(AND(ISNUMBER(Grupos!D11),ISNUMBER(Grupos!E11)),Grupos!D11,0) | F5: =IF(AND(ISNUMBER(Grupos!E8),ISNUMBER(Grupos!D8)),Grupos!D8,0)+IF(AND(ISNUMBER(Grupos!D9),ISNUMBER(Grupos!E9)),Grupos!E9,0)+IF(AND(ISNUMBER(Grupos!D11),ISNUMBER(Grupos!E11)),Grupos!E11,0) | G5: =E5-F5 | H5: =IF(AND(AND(ISNUMBER(Grupos!E8),ISNUMBER(Grupos!D8)),D4=D5),IF(Grupos!E8>Grupos!D8,3,IF(Grupos!E8=Grupos!D8,1,0)),0)+IF(AND(AND(ISNUMBER(Grupos!D9),ISNUMBER(Grupos!E9)),D3=D5),IF(Grupos!D9>Grupos!E9,3,IF(Grupos!D9=Grupos!E9,1,0)),0)+IF(AND(AND(ISNUMBER(Grupos!D11),ISNUMBER(Grupos!E11)),D2=D5),IF(Grupos!D11>Grupos!E11,3,IF(Grupos!D11=Grupos!E11,1,0)),0) | I5: =IF(AND(AND(ISNUMBER(Grupos!E8),ISNUMBER(Grupos!D8)),D4=D5),Grupos!E8-Grupos!D8,0)+IF(AND(AND(ISNUMBER(Grupos!D9),ISNUMBER(Grupos!E9)),D3=D5),Grupos!D9-Grupos!E9,0)+IF(AND(AND(ISNUMBER(Grupos!D11),ISNUMBER(Grupos!E11)),D2=D5),Grupos!D11-Grupos!E11,0) | J5: =IF(AND(AND(ISNUMBER(Grupos!E8),ISNUMBER(Grupos!D8)),D4=D5),Grupos!E8,0)+IF(AND(AND(ISNUMBER(Grupos!D9),ISNUMBER(Grupos!E9)),D3=D5),Grupos!D9,0)+IF(AND(AND(ISNUMBER(Grupos!D11),ISNUMBER(Grupos!E11)),D2=D5),Grupos!D11,0) | K5: =D5*100000000000+H5*1000000000+(I5+50)*10000000+J5*100000+(G5+50)*1000+E5*10+(4-C5) | L5: =RANK(K5,K2:K5,0)
A6: B | B6: CAN | C6: 1 | D6: =IF(AND(ISNUMBER(Grupos!D16),ISNUMBER(Grupos!E16)),IF(Grupos!D16>Grupos!E16,3,IF(Grupos!D16=Grupos!E16,1,0)),0)+IF(AND(ISNUMBER(Grupos!D19),ISNUMBER(Grupos!E19)),IF(Grupos!D19>Grupos!E19,3,IF(Grupos!D19=Grupos!E19,1,0)),0)+IF(AND(ISNUMBER(Grupos!E20),ISNUMBER(Grupos!D20)),IF(Grupos!E20>Grupos!D20,3,IF(Grupos!E20=Grupos!D20,1,0)),0) | E6: =IF(AND(ISNUMBER(Grupos!D16),ISNUMBER(Grupos!E16)),Grupos!D16,0)+IF(AND(ISNUMBER(Grupos!D19),ISNUMBER(Grupos!E19)),Grupos!D19,0)+IF(AND(ISNUMBER(Grupos!E20),ISNUMBER(Grupos!D20)),Grupos!E20,0) | F6: =IF(AND(ISNUMBER(Grupos!D16),ISNUMBER(Grupos!E16)),Grupos!E16,0)+IF(AND(ISNUMBER(Grupos!D19),ISNUMBER(Grupos!E19)),Grupos!E19,0)+IF(AND(ISNUMBER(Grupos!E20),ISNUMBER(Grupos!D20)),Grupos!D20,0) | G6: =E6-F6 | H6: =IF(AND(AND(ISNUMBER(Grupos!D16),ISNUMBER(Grupos!E16)),D7=D6),IF(Grupos!D16>Grupos!E16,3,IF(Grupos!D16=Grupos!E16,1,0)),0)+IF(AND(AND(ISNUMBER(Grupos!D19),ISNUMBER(Grupos!E19)),D8=D6),IF(Grupos!D19>Grupos!E19,3,IF(Grupos!D19=Grupos!E19,1,0)),0)+IF(AND(AND(ISNUMBER(Grupos!E20),ISNUMBER(Grupos!D20)),D9=D6),IF(Grupos!E20>Grupos!D20,3,IF(Grupos!E20=Grupos!D20,1,0)),0) | I6: =IF(AND(AND(ISNUMBER(Grupos!D16),ISNUMBER(Grupos!E16)),D7=D6),Grupos!D16-Grupos!E16,0)+IF(AND(AND(ISNUMBER(Grupos!D19),ISNUMBER(Grupos!E19)),D8=D6),Grupos!D19-Grupos!E19,0)+IF(AND(AND(ISNUMBER(Grupos!E20),ISNUMBER(Grupos!D20)),D9=D6),Grupos!E20-Grupos!D20,0) | J6: =IF(AND(AND(ISNUMBER(Grupos!D16),ISNUMBER(Grupos!E16)),D7=D6),Grupos!D16,0)+IF(AND(AND(ISNUMBER(Grupos!D19),ISNUMBER(Grupos!E19)),D8=D6),Grupos!D19,0)+IF(AND(AND(ISNUMBER(Grupos!E20),ISNUMBER(Grupos!D20)),D9=D6),Grupos!E20,0) | K6: =D6*100000000000+H6*1000000000+(I6+50)*10000000+J6*100000+(G6+50)*1000+E6*10+(4-C6) | L6: =RANK(K6,K6:K9,0) | N6: =INDEX(B6:B9,MATCH(1,L6:L9,0)) | O6: =INDEX(B6:B9,MATCH(2,L6:L9,0)) | P6: =INDEX(B6:B9,MATCH(3,L6:L9,0))
A7: B | B7: BIH | C7: 2 | D7: =IF(AND(ISNUMBER(Grupos!E16),ISNUMBER(Grupos!D16)),IF(Grupos!E16>Grupos!D16,3,IF(Grupos!E16=Grupos!D16,1,0)),0)+IF(AND(ISNUMBER(Grupos!E18),ISNUMBER(Grupos!D18)),IF(Grupos!E18>Grupos!D18,3,IF(Grupos!E18=Grupos!D18,1,0)),0)+IF(AND(ISNUMBER(Grupos!D21),ISNUMBER(Grupos!E21)),IF(Grupos!D21>Grupos!E21,3,IF(Grupos!D21=Grupos!E21,1,0)),0) | E7: =IF(AND(ISNUMBER(Grupos!E16),ISNUMBER(Grupos!D16)),Grupos!E16,0)+IF(AND(ISNUMBER(Grupos!E18),ISNUMBER(Grupos!D18)),Grupos!E18,0)+IF(AND(ISNUMBER(Grupos!D21),ISNUMBER(Grupos!E21)),Grupos!D21,0) | F7: =IF(AND(ISNUMBER(Grupos!E16),ISNUMBER(Grupos!D16)),Grupos!D16,0)+IF(AND(ISNUMBER(Grupos!E18),ISNUMBER(Grupos!D18)),Grupos!D18,0)+IF(AND(ISNUMBER(Grupos!D21),ISNUMBER(Grupos!E21)),Grupos!E21,0) | G7: =E7-F7 | H7: =IF(AND(AND(ISNUMBER(Grupos!E16),ISNUMBER(Grupos!D16)),D6=D7),IF(Grupos!E16>Grupos!D16,3,IF(Grupos!E16=Grupos!D16,1,0)),0)+IF(AND(AND(ISNUMBER(Grupos!E18),ISNUMBER(Grupos!D18)),D9=D7),IF(Grupos!E18>Grupos!D18,3,IF(Grupos!E18=Grupos!D18,1,0)),0)+IF(AND(AND(ISNUMBER(Grupos!D21),ISNUMBER(Grupos!E21)),D8=D7),IF(Grupos!D21>Grupos!E21,3,IF(Grupos!D21=Grupos!E21,1,0)),0) | I7: =IF(AND(AND(ISNUMBER(Grupos!E16),ISNUMBER(Grupos!D16)),D6=D7),Grupos!E16-Grupos!D16,0)+IF(AND(AND(ISNUMBER(Grupos!E18),ISNUMBER(Grupos!D18)),D9=D7),Grupos!E18-Grupos!D18,0)+IF(AND(AND(ISNUMBER(Grupos!D21),ISNUMBER(Grupos!E21)),D8=D7),Grupos!D21-Grupos!E21,0) | J7: =IF(AND(AND(ISNUMBER(Grupos!E16),ISNUMBER(Grupos!D16)),D6=D7),Grupos!E16,0)+IF(AND(AND(ISNUMBER(Grupos!E18),ISNUMBER(Grupos!D18)),D9=D7),Grupos!E18,0)+IF(AND(AND(ISNUMBER(Grupos!D21),ISNUMBER(Grupos!E21)),D8=D7),Grupos!D21,0) | K7: =D7*100000000000+H7*1000000000+(I7+50)*10000000+J7*100000+(G7+50)*1000+E7*10+(4-C7) | L7: =RANK(K7,K6:K9,0)
A8: B | B8: QAT | C8: 3 | D8: =IF(AND(ISNUMBER(Grupos!D17),ISNUMBER(Grupos!E17)),IF(Grupos!D17>Grupos!E17,3,IF(Grupos!D17=Grupos!E17,1,0)),0)+IF(AND(ISNUMBER(Grupos!E19),ISNUMBER(Grupos!D19)),IF(Grupos!E19>Grupos!D19,3,IF(Grupos!E19=Grupos!D19,1,0)),0)+IF(AND(ISNUMBER(Grupos!E21),ISNUMBER(Grupos!D21)),IF(Grupos!E21>Grupos!D21,3,IF(Grupos!E21=Grupos!D21,1,0)),0) | E8: =IF(AND(ISNUMBER(Grupos!D17),ISNUMBER(Grupos!E17)),Grupos!D17,0)+IF(AND(ISNUMBER(Grupos!E19),ISNUMBER(Grupos!D19)),Grupos!E19,0)+IF(AND(ISNUMBER(Grupos!E21),ISNUMBER(Grupos!D21)),Grupos!E21,0) | F8: =IF(AND(ISNUMBER(Grupos!D17),ISNUMBER(Grupos!E17)),Grupos!E17,0)+IF(AND(ISNUMBER(Grupos!E19),ISNUMBER(Grupos!D19)),Grupos!D19,0)+IF(AND(ISNUMBER(Grupos!E21),ISNUMBER(Grupos!D21)),Grupos!D21,0) | G8: =E8-F8 | H8: =IF(AND(AND(ISNUMBER(Grupos!D17),ISNUMBER(Grupos!E17)),D9=D8),IF(Grupos!D17>Grupos!E17,3,IF(Grupos!D17=Grupos!E17,1,0)),0)+IF(AND(AND(ISNUMBER(Grupos!E19),ISNUMBER(Grupos!D19)),D6=D8),IF(Grupos!E19>Grupos!D19,3,IF(Grupos!E19=Grupos!D19,1,0)),0)+IF(AND(AND(ISNUMBER(Grupos!E21),ISNUMBER(Grupos!D21)),D7=D8),IF(Grupos!E21>Grupos!D21,3,IF(Grupos!E21=Grupos!D21,1,0)),0) | I8: =IF(AND(AND(ISNUMBER(Grupos!D17),ISNUMBER(Grupos!E17)),D9=D8),Grupos!D17-Grupos!E17,0)+IF(AND(AND(ISNUMBER(Grupos!E19),ISNUMBER(Grupos!D19)),D6=D8),Grupos!E19-Grupos!D19,0)+IF(AND(AND(ISNUMBER(Grupos!E21),ISNUMBER(Grupos!D21)),D7=D8),Grupos!E21-Grupos!D21,0) | J8: =IF(AND(AND(ISNUMBER(Grupos!D17),ISNUMBER(Grupos!E17)),D9=D8),Grupos!D17,0)+IF(AND(AND(ISNUMBER(Grupos!E19),ISNUMBER(Grupos!D19)),D6=D8),Grupos!E19,0)+IF(AND(AND(ISNUMBER(Grupos!E21),ISNUMBER(Grupos!D21)),D7=D8),Grupos!E21,0) | K8: =D8*100000000000+H8*1000000000+(I8+50)*10000000+J8*100000+(G8+50)*1000+E8*10+(4-C8) | L8: =RANK(K8,K6:K9,0)
A9: B | B9: SUI | C9: 4 | D9: =IF(AND(ISNUMBER(Grupos!E17),ISNUMBER(Grupos!D17)),IF(Grupos!E17>Grupos!D17,3,IF(Grupos!E17=Grupos!D17,1,0)),0)+IF(AND(ISNUMBER(Grupos!D18),ISNUMBER(Grupos!E18)),IF(Grupos!D18>Grupos!E18,3,IF(Grupos!D18=Grupos!E18,1,0)),0)+IF(AND(ISNUMBER(Grupos!D20),ISNUMBER(Grupos!E20)),IF(Grupos!D20>Grupos!E20,3,IF(Grupos!D20=Grupos!E20,1,0)),0) | E9: =IF(AND(ISNUMBER(Grupos!E17),ISNUMBER(Grupos!D17)),Grupos!E17,0)+IF(AND(ISNUMBER(Grupos!D18),ISNUMBER(Grupos!E18)),Grupos!D18,0)+IF(AND(ISNUMBER(Grupos!D20),ISNUMBER(Grupos!E20)),Grupos!D20,0) | F9: =IF(AND(ISNUMBER(Grupos!E17),ISNUMBER(Grupos!D17)),Grupos!D17,0)+IF(AND(ISNUMBER(Grupos!D18),ISNUMBER(Grupos!E18)),Grupos!E18,0)+IF(AND(ISNUMBER(Grupos!D20),ISNUMBER(Grupos!E20)),Grupos!E20,0) | G9: =E9-F9 | H9: =IF(AND(AND(ISNUMBER(Grupos!E17),ISNUMBER(Grupos!D17)),D8=D9),IF(Grupos!E17>Grupos!D17,3,IF(Grupos!E17=Grupos!D17,1,0)),0)+IF(AND(AND(ISNUMBER(Grupos!D18),ISNUMBER(Grupos!E18)),D7=D9),IF(Grupos!D18>Grupos!E18,3,IF(Grupos!D18=Grupos!E18,1,0)),0)+IF(AND(AND(ISNUMBER(Grupos!D20),ISNUMBER(Grupos!E20)),D6=D9),IF(Grupos!D20>Grupos!E20,3,IF(Grupos!D20=Grupos!E20,1,0)),0) | I9: =IF(AND(AND(ISNUMBER(Grupos!E17),ISNUMBER(Grupos!D17)),D8=D9),Grupos!E17-Grupos!D17,0)+IF(AND(AND(ISNUMBER(Grupos!D18),ISNUMBER(Grupos!E18)),D7=D9),Grupos!D18-Grupos!E18,0)+IF(AND(AND(ISNUMBER(Grupos!D20),ISNUMBER(Grupos!E20)),D6=D9),Grupos!D20-Grupos!E20,0) | J9: =IF(AND(AND(ISNUMBER(Grupos!E17),ISNUMBER(Grupos!D17)),D8=D9),Grupos!E17,0)+IF(AND(AND(ISNUMBER(Grupos!D18),ISNUMBER(Grupos!E18)),D7=D9),Grupos!D18,0)+IF(AND(AND(ISNUMBER(Grupos!D20),ISNUMBER(Grupos!E20)),D6=D9),Grupos!D20,0) | K9: =D9*100000000000+H9*1000000000+(I9+50)*10000000+J9*100000+(G9+50)*1000+E9*10+(4-C9) | L9: =RANK(K9,K6:K9,0)
A10: C | B10: BRA | C10: 1 | D10: =IF(AND(ISNUMBER(Grupos!D25),ISNUMBER(Grupos!E25)),IF(Grupos!D25>Grupos!E25,3,IF(Grupos!D25=Grupos!E25,1,0)),0)+IF(AND(ISNUMBER(Grupos!D28),ISNUMBER(Grupos!E28)),IF(Grupos!D28>Grupos!E28,3,IF(Grupos!D28=Grupos!E28,1,0)),0)+IF(AND(ISNUMBER(Grupos!E29),ISNUMBER(Grupos!D29)),IF(Grupos!E29>Grupos!D29,3,IF(Grupos!E29=Grupos!D29,1,0)),0) | E10: =IF(AND(ISNUMBER(Grupos!D25),ISNUMBER(Grupos!E25)),Grupos!D25,0)+IF(AND(ISNUMBER(Grupos!D28),ISNUMBER(Grupos!E28)),Grupos!D28,0)+IF(AND(ISNUMBER(Grupos!E29),ISNUMBER(Grupos!D29)),Grupos!E29,0) | F10: =IF(AND(ISNUMBER(Grupos!D25),ISNUMBER(Grupos!E25)),Grupos!E25,0)+IF(AND(ISNUMBER(Grupos!D28),ISNUMBER(Grupos!E28)),Grupos!E28,0)+IF(AND(ISNUMBER(Grupos!E29),ISNUMBER(Grupos!D29)),Grupos!D29,0) | G10: =E10-F10 | H10: =IF(AND(AND(ISNUMBER(Grupos!D25),ISNUMBER(Grupos!E25)),D11=D10),IF(Grupos!D25>Grupos!E25,3,IF(Grupos!D25=Grupos!E25,1,0)),0)+IF(AND(AND(ISNUMBER(Grupos!D28),ISNUMBER(Grupos!E28)),D12=D10),IF(Grupos!D28>Grupos!E28,3,IF(Grupos!D28=Grupos!E28,1,0)),0)+IF(AND(AND(ISNUMBER(Grupos!E29),ISNUMBER(Grupos!D29)),D13=D10),IF(Grupos!E29>Grupos!D29,3,IF(Grupos!E29=Grupos!D29,1,0)),0) | I10: =IF(AND(AND(ISNUMBER(Grupos!D25),ISNUMBER(Grupos!E25)),D11=D10),Grupos!D25-Grupos!E25,0)+IF(AND(AND(ISNUMBER(Grupos!D28),ISNUMBER(Grupos!E28)),D12=D10),Grupos!D28-Grupos!E28,0)+IF(AND(AND(ISNUMBER(Grupos!E29),ISNUMBER(Grupos!D29)),D13=D10),Grupos!E29-Grupos!D29,0) | J10: =IF(AND(AND(ISNUMBER(Grupos!D25),ISNUMBER(Grupos!E25)),D11=D10),Grupos!D25,0)+IF(AND(AND(ISNUMBER(Grupos!D28),ISNUMBER(Grupos!E28)),D12=D10),Grupos!D28,0)+IF(AND(AND(ISNUMBER(Grupos!E29),ISNUMBER(Grupos!D29)),D13=D10),Grupos!E29,0) | K10: =D10*100000000000+H10*1000000000+(I10+50)*10000000+J10*100000+(G10+50)*1000+E10*10+(4-C10) | L10: =RANK(K10,K10:K13,0) | N10: =INDEX(B10:B13,MATCH(1,L10:L13,0)) | O10: =INDEX(B10:B13,MATCH(2,L10:L13,0)) | P10: =INDEX(B10:B13,MATCH(3,L10:L13,0))
A11: C | B11: MAR | C11: 2 | D11: =IF(AND(ISNUMBER(Grupos!E25),ISNUMBER(Grupos!D25)),IF(Grupos!E25>Grupos!D25,3,IF(Grupos!E25=Grupos!D25,1,0)),0)+IF(AND(ISNUMBER(Grupos!E27),ISNUMBER(Grupos!D27)),IF(Grupos!E27>Grupos!D27,3,IF(Grupos!E27=Grupos!D27,1,0)),0)+IF(AND(ISNUMBER(Grupos!D30),ISNUMBER(Grupos!E30)),IF(Grupos!D30>Grupos!E30,3,IF(Grupos!D30=Grupos!E30,1,0)),0) | E11: =IF(AND(ISNUMBER(Grupos!E25),ISNUMBER(Grupos!D25)),Grupos!E25,0)+IF(AND(ISNUMBER(Grupos!E27),ISNUMBER(Grupos!D27)),Grupos!E27,0)+IF(AND(ISNUMBER(Grupos!D30),ISNUMBER(Grupos!E30)),Grupos!D30,0) | F11: =IF(AND(ISNUMBER(Grupos!E25),ISNUMBER(Grupos!D25)),Grupos!D25,0)+IF(AND(ISNUMBER(Grupos!E27),ISNUMBER(Grupos!D27)),Grupos!D27,0)+IF(AND(ISNUMBER(Grupos!D30),ISNUMBER(Grupos!E30)),Grupos!E30,0) | G11: =E11-F11 | H11: =IF(AND(AND(ISNUMBER(Grupos!E25),ISNUMBER(Grupos!D25)),D10=D11),IF(Grupos!E25>Grupos!D25,3,IF(Grupos!E25=Grupos!D25,1,0)),0)+IF(AND(AND(ISNUMBER(Grupos!E27),ISNUMBER(Grupos!D27)),D13=D11),IF(Grupos!E27>Grupos!D27,3,IF(Grupos!E27=Grupos!D27,1,0)),0)+IF(AND(AND(ISNUMBER(Grupos!D30),ISNUMBER(Grupos!E30)),D12=D11),IF(Grupos!D30>Grupos!E30,3,IF(Grupos!D30=Grupos!E30,1,0)),0) | I11: =IF(AND(AND(ISNUMBER(Grupos!E25),ISNUMBER(Grupos!D25)),D10=D11),Grupos!E25-Grupos!D25,0)+IF(AND(AND(ISNUMBER(Grupos!E27),ISNUMBER(Grupos!D27)),D13=D11),Grupos!E27-Grupos!D27,0)+IF(AND(AND(ISNUMBER(Grupos!D30),ISNUMBER(Grupos!E30)),D12=D11),Grupos!D30-Grupos!E30,0) | J11: =IF(AND(AND(ISNUMBER(Grupos!E25),ISNUMBER(Grupos!D25)),D10=D11),Grupos!E25,0)+IF(AND(AND(ISNUMBER(Grupos!E27),ISNUMBER(Grupos!D27)),D13=D11),Grupos!E27,0)+IF(AND(AND(ISNUMBER(Grupos!D30),ISNUMBER(Grupos!E30)),D12=D11),Grupos!D30,0) | K11: =D11*100000000000+H11*1000000000+(I11+50)*10000000+J11*100000+(G11+50)*1000+E11*10+(4-C11) | L11: =RANK(K11,K10:K13,0)
A12: C | B12: HAI | C12: 3 | D12: =IF(AND(ISNUMBER(Grupos!D26),ISNUMBER(Grupos!E26)),IF(Grupos!D26>Grupos!E26,3,IF(Grupos!D26=Grupos!E26,1,0)),0)+IF(AND(ISNUMBER(Grupos!E28),ISNUMBER(Grupos!D28)),IF(Grupos!E28>Grupos!D28,3,IF(Grupos!E28=Grupos!D28,1,0)),0)+IF(AND(ISNUMBER(Grupos!E30),ISNUMBER(Grupos!D30)),IF(Grupos!E30>Grupos!D30,3,IF(Grupos!E30=Grupos!D30,1,0)),0) | E12: =IF(AND(ISNUMBER(Grupos!D26),ISNUMBER(Grupos!E26)),Grupos!D26,0)+IF(AND(ISNUMBER(Grupos!E28),ISNUMBER(Grupos!D28)),Grupos!E28,0)+IF(AND(ISNUMBER(Grupos!E30),ISNUMBER(Grupos!D30)),Grupos!E30,0) | F12: =IF(AND(ISNUMBER(Grupos!D26),ISNUMBER(Grupos!E26)),Grupos!E26,0)+IF(AND(ISNUMBER(Grupos!E28),ISNUMBER(Grupos!D28)),Grupos!D28,0)+IF(AND(ISNUMBER(Grupos!E30),ISNUMBER(Grupos!D30)),Grupos!D30,0) | G12: =E12-F12 | H12: =IF(AND(AND(ISNUMBER(Grupos!D26),ISNUMBER(Grupos!E26)),D13=D12),IF(Grupos!D26>Grupos!E26,3,IF(Grupos!D26=Grupos!E26,1,0)),0)+IF(AND(AND(ISNUMBER(Grupos!E28),ISNUMBER(Grupos!D28)),D10=D12),IF(Grupos!E28>Grupos!D28,3,IF(Grupos!E28=Grupos!D28,1,0)),0)+IF(AND(AND(ISNUMBER(Grupos!E30),ISNUMBER(Grupos!D30)),D11=D12),IF(Grupos!E30>Grupos!D30,3,IF(Grupos!E30=Grupos!D30,1,0)),0) | I12: =IF(AND(AND(ISNUMBER(Grupos!D26),ISNUMBER(Grupos!E26)),D13=D12),Grupos!D26-Grupos!E26,0)+IF(AND(AND(ISNUMBER(Grupos!E28),ISNUMBER(Grupos!D28)),D10=D12),Grupos!E28-Grupos!D28,0)+IF(AND(AND(ISNUMBER(Grupos!E30),ISNUMBER(Grupos!D30)),D11=D12),Grupos!E30-Grupos!D30,0) | J12: =IF(AND(AND(ISNUMBER(Grupos!D26),ISNUMBER(Grupos!E26)),D13=D12),Grupos!D26,0)+IF(AND(AND(ISNUMBER(Grupos!E28),ISNUMBER(Grupos!D28)),D10=D12),Grupos!E28,0)+IF(AND(AND(ISNUMBER(Grupos!E30),ISNUMBER(Grupos!D30)),D11=D12),Grupos!E30,0) | K12: =D12*100000000000+H12*1000000000+(I12+50)*10000000+J12*100000+(G12+50)*1000+E12*10+(4-C12) | L12: =RANK(K12,K10:K13,0)
A13: C | B13: SCO | C13: 4 | D13: =IF(AND(ISNUMBER(Grupos!E26),ISNUMBER(Grupos!D26)),IF(Grupos!E26>Grupos!D26,3,IF(Grupos!E26=Grupos!D26,1,0)),0)+IF(AND(ISNUMBER(Grupos!D27),ISNUMBER(Grupos!E27)),IF(Grupos!D27>Grupos!E27,3,IF(Grupos!D27=Grupos!E27,1,0)),0)+IF(AND(ISNUMBER(Grupos!D29),ISNUMBER(Grupos!E29)),IF(Grupos!D29>Grupos!E29,3,IF(Grupos!D29=Grupos!E29,1,0)),0) | E13: =IF(AND(ISNUMBER(Grupos!E26),ISNUMBER(Grupos!D26)),Grupos!E26,0)+IF(AND(ISNUMBER(Grupos!D27),ISNUMBER(Grupos!E27)),Grupos!D27,0)+IF(AND(ISNUMBER(Grupos!D29),ISNUMBER(Grupos!E29)),Grupos!D29,0) | F13: =IF(AND(ISNUMBER(Grupos!E26),ISNUMBER(Grupos!D26)),Grupos!D26,0)+IF(AND(ISNUMBER(Grupos!D27),ISNUMBER(Grupos!E27)),Grupos!E27,0)+IF(AND(ISNUMBER(Grupos!D29),ISNUMBER(Grupos!E29)),Grupos!E29,0) | G13: =E13-F13 | H13: =IF(AND(AND(ISNUMBER(Grupos!E26),ISNUMBER(Grupos!D26)),D12=D13),IF(Grupos!E26>Grupos!D26,3,IF(Grupos!E26=Grupos!D26,1,0)),0)+IF(AND(AND(ISNUMBER(Grupos!D27),ISNUMBER(Grupos!E27)),D11=D13),IF(Grupos!D27>Grupos!E27,3,IF(Grupos!D27=Grupos!E27,1,0)),0)+IF(AND(AND(ISNUMBER(Grupos!D29),ISNUMBER(Grupos!E29)),D10=D13),IF(Grupos!D29>Grupos!E29,3,IF(Grupos!D29=Grupos!E29,1,0)),0) | I13: =IF(AND(AND(ISNUMBER(Grupos!E26),ISNUMBER(Grupos!D26)),D12=D13),Grupos!E26-Grupos!D26,0)+IF(AND(AND(ISNUMBER(Grupos!D27),ISNUMBER(Grupos!E27)),D11=D13),Grupos!D27-Grupos!E27,0)+IF(AND(AND(ISNUMBER(Grupos!D29),ISNUMBER(Grupos!E29)),D10=D13),Grupos!D29-Grupos!E29,0) | J13: =IF(AND(AND(ISNUMBER(Grupos!E26),ISNUMBER(Grupos!D26)),D12=D13),Grupos!E26,0)+IF(AND(AND(ISNUMBER(Grupos!D27),ISNUMBER(Grupos!E27)),D11=D13),Grupos!D27,0)+IF(AND(AND(ISNUMBER(Grupos!D29),ISNUMBER(Grupos!E29)),D10=D13),Grupos!D29,0) | K13: =D13*100000000000+H13*1000000000+(I13+50)*10000000+J13*100000+(G13+50)*1000+E13*10+(4-C13) | L13: =RANK(K13,K10:K13,0)
A14: D | B14: USA | C14: 1 | D14: =IF(AND(ISNUMBER(Grupos!D34),ISNUMBER(Grupos!E34)),IF(Grupos!D34>Grupos!E34,3,IF(Grupos!D34=Grupos!E34,1,0)),0)+IF(AND(ISNUMBER(Grupos!D36),ISNUMBER(Grupos!E36)),IF(Grupos!D36>Grupos!E36,3,IF(Grupos!D36=Grupos!E36,1,0)),0)+IF(AND(ISNUMBER(Grupos!E38),ISNUMBER(Grupos!D38)),IF(Grupos!E38>Grupos!D38,3,IF(Grupos!E38=Grupos!D38,1,0)),0) | E14: =IF(AND(ISNUMBER(Grupos!D34),ISNUMBER(Grupos!E34)),Grupos!D34,0)+IF(AND(ISNUMBER(Grupos!D36),ISNUMBER(Grupos!E36)),Grupos!D36,0)+IF(AND(ISNUMBER(Grupos!E38),ISNUMBER(Grupos!D38)),Grupos!E38,0) | F14: =IF(AND(ISNUMBER(Grupos!D34),ISNUMBER(Grupos!E34)),Grupos!E34,0)+IF(AND(ISNUMBER(Grupos!D36),ISNUMBER(Grupos!E36)),Grupos!E36,0)+IF(AND(ISNUMBER(Grupos!E38),ISNUMBER(Grupos!D38)),Grupos!D38,0) | G14: =E14-F14 | H14: =IF(AND(AND(ISNUMBER(Grupos!D34),ISNUMBER(Grupos!E34)),D15=D14),IF(Grupos!D34>Grupos!E34,3,IF(Grupos!D34=Grupos!E34,1,0)),0)+IF(AND(AND(ISNUMBER(Grupos!D36),ISNUMBER(Grupos!E36)),D16=D14),IF(Grupos!D36>Grupos!E36,3,IF(Grupos!D36=Grupos!E36,1,0)),0)+IF(AND(AND(ISNUMBER(Grupos!E38),ISNUMBER(Grupos!D38)),D17=D14),IF(Grupos!E38>Grupos!D38,3,IF(Grupos!E38=Grupos!D38,1,0)),0) | I14: =IF(AND(AND(ISNUMBER(Grupos!D34),ISNUMBER(Grupos!E34)),D15=D14),Grupos!D34-Grupos!E34,0)+IF(AND(AND(ISNUMBER(Grupos!D36),ISNUMBER(Grupos!E36)),D16=D14),Grupos!D36-Grupos!E36,0)+IF(AND(AND(ISNUMBER(Grupos!E38),ISNUMBER(Grupos!D38)),D17=D14),Grupos!E38-Grupos!D38,0) | J14: =IF(AND(AND(ISNUMBER(Grupos!D34),ISNUMBER(Grupos!E34)),D15=D14),Grupos!D34,0)+IF(AND(AND(ISNUMBER(Grupos!D36),ISNUMBER(Grupos!E36)),D16=D14),Grupos!D36,0)+IF(AND(AND(ISNUMBER(Grupos!E38),ISNUMBER(Grupos!D38)),D17=D14),Grupos!E38,0) | K14: =D14*100000000000+H14*1000000000+(I14+50)*10000000+J14*100000+(G14+50)*1000+E14*10+(4-C14) | L14: =RANK(K14,K14:K17,0) | N14: =INDEX(B14:B17,MATCH(1,L14:L17,0)) | O14: =INDEX(B14:B17,MATCH(2,L14:L17,0)) | P14: =INDEX(B14:B17,MATCH(3,L14:L17,0))
A15: D | B15: PAR | C15: 2 | D15: =IF(AND(ISNUMBER(Grupos!E34),ISNUMBER(Grupos!D34)),IF(Grupos!E34>Grupos!D34,3,IF(Grupos!E34=Grupos!D34,1,0)),0)+IF(AND(ISNUMBER(Grupos!E37),ISNUMBER(Grupos!D37)),IF(Grupos!E37>Grupos!D37,3,IF(Grupos!E37=Grupos!D37,1,0)),0)+IF(AND(ISNUMBER(Grupos!D39),ISNUMBER(Grupos!E39)),IF(Grupos!D39>Grupos!E39,3,IF(Grupos!D39=Grupos!E39,1,0)),0) | E15: =IF(AND(ISNUMBER(Grupos!E34),ISNUMBER(Grupos!D34)),Grupos!E34,0)+IF(AND(ISNUMBER(Grupos!E37),ISNUMBER(Grupos!D37)),Grupos!E37,0)+IF(AND(ISNUMBER(Grupos!D39),ISNUMBER(Grupos!E39)),Grupos!D39,0) | F15: =IF(AND(ISNUMBER(Grupos!E34),ISNUMBER(Grupos!D34)),Grupos!D34,0)+IF(AND(ISNUMBER(Grupos!E37),ISNUMBER(Grupos!D37)),Grupos!D37,0)+IF(AND(ISNUMBER(Grupos!D39),ISNUMBER(Grupos!E39)),Grupos!E39,0) | G15: =E15-F15 | H15: =IF(AND(AND(ISNUMBER(Grupos!E34),ISNUMBER(Grupos!D34)),D14=D15),IF(Grupos!E34>Grupos!D34,3,IF(Grupos!E34=Grupos!D34,1,0)),0)+IF(AND(AND(ISNUMBER(Grupos!E37),ISNUMBER(Grupos!D37)),D17=D15),IF(Grupos!E37>Grupos!D37,3,IF(Grupos!E37=Grupos!D37,1,0)),0)+IF(AND(AND(ISNUMBER(Grupos!D39),ISNUMBER(Grupos!E39)),D16=D15),IF(Grupos!D39>Grupos!E39,3,IF(Grupos!D39=Grupos!E39,1,0)),0) | I15: =IF(AND(AND(ISNUMBER(Grupos!E34),ISNUMBER(Grupos!D34)),D14=D15),Grupos!E34-Grupos!D34,0)+IF(AND(AND(ISNUMBER(Grupos!E37),ISNUMBER(Grupos!D37)),D17=D15),Grupos!E37-Grupos!D37,0)+IF(AND(AND(ISNUMBER(Grupos!D39),ISNUMBER(Grupos!E39)),D16=D15),Grupos!D39-Grupos!E39,0) | J15: =IF(AND(AND(ISNUMBER(Grupos!E34),ISNUMBER(Grupos!D34)),D14=D15),Grupos!E34,0)+IF(AND(AND(ISNUMBER(Grupos!E37),ISNUMBER(Grupos!D37)),D17=D15),Grupos!E37,0)+IF(AND(AND(ISNUMBER(Grupos!D39),ISNUMBER(Grupos!E39)),D16=D15),Grupos!D39,0) | K15: =D15*100000000000+H15*1000000000+(I15+50)*10000000+J15*100000+(G15+50)*1000+E15*10+(4-C15) | L15: =RANK(K15,K14:K17,0)
A16: D | B16: AUS | C16: 3 | D16: =IF(AND(ISNUMBER(Grupos!D35),ISNUMBER(Grupos!E35)),IF(Grupos!D35>Grupos!E35,3,IF(Grupos!D35=Grupos!E35,1,0)),0)+IF(AND(ISNUMBER(Grupos!E36),ISNUMBER(Grupos!D36)),IF(Grupos!E36>Grupos!D36,3,IF(Grupos!E36=Grupos!D36,1,0)),0)+IF(AND(ISNUMBER(Grupos!E39),ISNUMBER(Grupos!D39)),IF(Grupos!E39>Grupos!D39,3,IF(Grupos!E39=Grupos!D39,1,0)),0) | E16: =IF(AND(ISNUMBER(Grupos!D35),ISNUMBER(Grupos!E35)),Grupos!D35,0)+IF(AND(ISNUMBER(Grupos!E36),ISNUMBER(Grupos!D36)),Grupos!E36,0)+IF(AND(ISNUMBER(Grupos!E39),ISNUMBER(Grupos!D39)),Grupos!E39,0) | F16: =IF(AND(ISNUMBER(Grupos!D35),ISNUMBER(Grupos!E35)),Grupos!E35,0)+IF(AND(ISNUMBER(Grupos!E36),ISNUMBER(Grupos!D36)),Grupos!D36,0)+IF(AND(ISNUMBER(Grupos!E39),ISNUMBER(Grupos!D39)),Grupos!D39,0) | G16: =E16-F16 | H16: =IF(AND(AND(ISNUMBER(Grupos!D35),ISNUMBER(Grupos!E35)),D17=D16),IF(Grupos!D35>Grupos!E35,3,IF(Grupos!D35=Grupos!E35,1,0)),0)+IF(AND(AND(ISNUMBER(Grupos!E36),ISNUMBER(Grupos!D36)),D14=D16),IF(Grupos!E36>Grupos!D36,3,IF(Grupos!E36=Grupos!D36,1,0)),0)+IF(AND(AND(ISNUMBER(Grupos!E39),ISNUMBER(Grupos!D39)),D15=D16),IF(Grupos!E39>Grupos!D39,3,IF(Grupos!E39=Grupos!D39,1,0)),0) | I16: =IF(AND(AND(ISNUMBER(Grupos!D35),ISNUMBER(Grupos!E35)),D17=D16),Grupos!D35-Grupos!E35,0)+IF(AND(AND(ISNUMBER(Grupos!E36),ISNUMBER(Grupos!D36)),D14=D16),Grupos!E36-Grupos!D36,0)+IF(AND(AND(ISNUMBER(Grupos!E39),ISNUMBER(Grupos!D39)),D15=D16),Grupos!E39-Grupos!D39,0) | J16: =IF(AND(AND(ISNUMBER(Grupos!D35),ISNUMBER(Grupos!E35)),D17=D16),Grupos!D35,0)+IF(AND(AND(ISNUMBER(Grupos!E36),ISNUMBER(Grupos!D36)),D14=D16),Grupos!E36,0)+IF(AND(AND(ISNUMBER(Grupos!E39),ISNUMBER(Grupos!D39)),D15=D16),Grupos!E39,0) | K16: =D16*100000000000+H16*1000000000+(I16+50)*10000000+J16*100000+(G16+50)*1000+E16*10+(4-C16) | L16: =RANK(K16,K14:K17,0)
A17: D | B17: TUR | C17: 4 | D17: =IF(AND(ISNUMBER(Grupos!E35),ISNUMBER(Grupos!D35)),IF(Grupos!E35>Grupos!D35,3,IF(Grupos!E35=Grupos!D35,1,0)),0)+IF(AND(ISNUMBER(Grupos!D37),ISNUMBER(Grupos!E37)),IF(Grupos!D37>Grupos!E37,3,IF(Grupos!D37=Grupos!E37,1,0)),0)+IF(AND(ISNUMBER(Grupos!D38),ISNUMBER(Grupos!E38)),IF(Grupos!D38>Grupos!E38,3,IF(Grupos!D38=Grupos!E38,1,0)),0) | E17: =IF(AND(ISNUMBER(Grupos!E35),ISNUMBER(Grupos!D35)),Grupos!E35,0)+IF(AND(ISNUMBER(Grupos!D37),ISNUMBER(Grupos!E37)),Grupos!D37,0)+IF(AND(ISNUMBER(Grupos!D38),ISNUMBER(Grupos!E38)),Grupos!D38,0) | F17: =IF(AND(ISNUMBER(Grupos!E35),ISNUMBER(Grupos!D35)),Grupos!D35,0)+IF(AND(ISNUMBER(Grupos!D37),ISNUMBER(Grupos!E37)),Grupos!E37,0)+IF(AND(ISNUMBER(Grupos!D38),ISNUMBER(Grupos!E38)),Grupos!E38,0) | G17: =E17-F17 | H17: =IF(AND(AND(ISNUMBER(Grupos!E35),ISNUMBER(Grupos!D35)),D16=D17),IF(Grupos!E35>Grupos!D35,3,IF(Grupos!E35=Grupos!D35,1,0)),0)+IF(AND(AND(ISNUMBER(Grupos!D37),ISNUMBER(Grupos!E37)),D15=D17),IF(Grupos!D37>Grupos!E37,3,IF(Grupos!D37=Grupos!E37,1,0)),0)+IF(AND(AND(ISNUMBER(Grupos!D38),ISNUMBER(Grupos!E38)),D14=D17),IF(Grupos!D38>Grupos!E38,3,IF(Grupos!D38=Grupos!E38,1,0)),0) | I17: =IF(AND(AND(ISNUMBER(Grupos!E35),ISNUMBER(Grupos!D35)),D16=D17),Grupos!E35-Grupos!D35,0)+IF(AND(AND(ISNUMBER(Grupos!D37),ISNUMBER(Grupos!E37)),D15=D17),Grupos!D37-Grupos!E37,0)+IF(AND(AND(ISNUMBER(Grupos!D38),ISNUMBER(Grupos!E38)),D14=D17),Grupos!D38-Grupos!E38,0) | J17: =IF(AND(AND(ISNUMBER(Grupos!E35),ISNUMBER(Grupos!D35)),D16=D17),Grupos!E35,0)+IF(AND(AND(ISNUMBER(Grupos!D37),ISNUMBER(Grupos!E37)),D15=D17),Grupos!D37,0)+IF(AND(AND(ISNUMBER(Grupos!D38),ISNUMBER(Grupos!E38)),D14=D17),Grupos!D38,0) | K17: =D17*100000000000+H17*1000000000+(I17+50)*10000000+J17*100000+(G17+50)*1000+E17*10+(4-C17) | L17: =RANK(K17,K14:K17,0)
A18: E | B18: GER | C18: 1 | D18: =IF(AND(ISNUMBER(Grupos!D43),ISNUMBER(Grupos!E43)),IF(Grupos!D43>Grupos!E43,3,IF(Grupos!D43=Grupos!E43,1,0)),0)+IF(AND(ISNUMBER(Grupos!D45),ISNUMBER(Grupos!E45)),IF(Grupos!D45>Grupos!E45,3,IF(Grupos!D45=Grupos!E45,1,0)),0)+IF(AND(ISNUMBER(Grupos!E48),ISNUMBER(Grupos!D48)),IF(Grupos!E48>Grupos!D48,3,IF(Grupos!E48=Grupos!D48,1,0)),0) | E18: =IF(AND(ISNUMBER(Grupos!D43),ISNUMBER(Grupos!E43)),Grupos!D43,0)+IF(AND(ISNUMBER(Grupos!D45),ISNUMBER(Grupos!E45)),Grupos!D45,0)+IF(AND(ISNUMBER(Grupos!E48),ISNUMBER(Grupos!D48)),Grupos!E48,0) | F18: =IF(AND(ISNUMBER(Grupos!D43),ISNUMBER(Grupos!E43)),Grupos!E43,0)+IF(AND(ISNUMBER(Grupos!D45),ISNUMBER(Grupos!E45)),Grupos!E45,0)+IF(AND(ISNUMBER(Grupos!E48),ISNUMBER(Grupos!D48)),Grupos!D48,0) | G18: =E18-F18 | H18: =IF(AND(AND(ISNUMBER(Grupos!D43),ISNUMBER(Grupos!E43)),D19=D18),IF(Grupos!D43>Grupos!E43,3,IF(Grupos!D43=Grupos!E43,1,0)),0)+IF(AND(AND(ISNUMBER(Grupos!D45),ISNUMBER(Grupos!E45)),D20=D18),IF(Grupos!D45>Grupos!E45,3,IF(Grupos!D45=Grupos!E45,1,0)),0)+IF(AND(AND(ISNUMBER(Grupos!E48),ISNUMBER(Grupos!D48)),D21=D18),IF(Grupos!E48>Grupos!D48,3,IF(Grupos!E48=Grupos!D48,1,0)),0) | I18: =IF(AND(AND(ISNUMBER(Grupos!D43),ISNUMBER(Grupos!E43)),D19=D18),Grupos!D43-Grupos!E43,0)+IF(AND(AND(ISNUMBER(Grupos!D45),ISNUMBER(Grupos!E45)),D20=D18),Grupos!D45-Grupos!E45,0)+IF(AND(AND(ISNUMBER(Grupos!E48),ISNUMBER(Grupos!D48)),D21=D18),Grupos!E48-Grupos!D48,0) | J18: =IF(AND(AND(ISNUMBER(Grupos!D43),ISNUMBER(Grupos!E43)),D19=D18),Grupos!D43,0)+IF(AND(AND(ISNUMBER(Grupos!D45),ISNUMBER(Grupos!E45)),D20=D18),Grupos!D45,0)+IF(AND(AND(ISNUMBER(Grupos!E48),ISNUMBER(Grupos!D48)),D21=D18),Grupos!E48,0) | K18: =D18*100000000000+H18*1000000000+(I18+50)*10000000+J18*100000+(G18+50)*1000+E18*10+(4-C18) | L18: =RANK(K18,K18:K21,0) | N18: =INDEX(B18:B21,MATCH(1,L18:L21,0)) | O18: =INDEX(B18:B21,MATCH(2,L18:L21,0)) | P18: =INDEX(B18:B21,MATCH(3,L18:L21,0))
A19: E | B19: CUW | C19: 2 | D19: =IF(AND(ISNUMBER(Grupos!E43),ISNUMBER(Grupos!D43)),IF(Grupos!E43>Grupos!D43,3,IF(Grupos!E43=Grupos!D43,1,0)),0)+IF(AND(ISNUMBER(Grupos!E46),ISNUMBER(Grupos!D46)),IF(Grupos!E46>Grupos!D46,3,IF(Grupos!E46=Grupos!D46,1,0)),0)+IF(AND(ISNUMBER(Grupos!D47),ISNUMBER(Grupos!E47)),IF(Grupos!D47>Grupos!E47,3,IF(Grupos!D47=Grupos!E47,1,0)),0) | E19: =IF(AND(ISNUMBER(Grupos!E43),ISNUMBER(Grupos!D43)),Grupos!E43,0)+IF(AND(ISNUMBER(Grupos!E46),ISNUMBER(Grupos!D46)),Grupos!E46,0)+IF(AND(ISNUMBER(Grupos!D47),ISNUMBER(Grupos!E47)),Grupos!D47,0) | F19: =IF(AND(ISNUMBER(Grupos!E43),ISNUMBER(Grupos!D43)),Grupos!D43,0)+IF(AND(ISNUMBER(Grupos!E46),ISNUMBER(Grupos!D46)),Grupos!D46,0)+IF(AND(ISNUMBER(Grupos!D47),ISNUMBER(Grupos!E47)),Grupos!E47,0) | G19: =E19-F19 | H19: =IF(AND(AND(ISNUMBER(Grupos!E43),ISNUMBER(Grupos!D43)),D18=D19),IF(Grupos!E43>Grupos!D43,3,IF(Grupos!E43=Grupos!D43,1,0)),0)+IF(AND(AND(ISNUMBER(Grupos!E46),ISNUMBER(Grupos!D46)),D21=D19),IF(Grupos!E46>Grupos!D46,3,IF(Grupos!E46=Grupos!D46,1,0)),0)+IF(AND(AND(ISNUMBER(Grupos!D47),ISNUMBER(Grupos!E47)),D20=D19),IF(Grupos!D47>Grupos!E47,3,IF(Grupos!D47=Grupos!E47,1,0)),0) | I19: =IF(AND(AND(ISNUMBER(Grupos!E43),ISNUMBER(Grupos!D43)),D18=D19),Grupos!E43-Grupos!D43,0)+IF(AND(AND(ISNUMBER(Grupos!E46),ISNUMBER(Grupos!D46)),D21=D19),Grupos!E46-Grupos!D46,0)+IF(AND(AND(ISNUMBER(Grupos!D47),ISNUMBER(Grupos!E47)),D20=D19),Grupos!D47-Grupos!E47,0) | J19: =IF(AND(AND(ISNUMBER(Grupos!E43),ISNUMBER(Grupos!D43)),D18=D19),Grupos!E43,0)+IF(AND(AND(ISNUMBER(Grupos!E46),ISNUMBER(Grupos!D46)),D21=D19),Grupos!E46,0)+IF(AND(AND(ISNUMBER(Grupos!D47),ISNUMBER(Grupos!E47)),D20=D19),Grupos!D47,0) | K19: =D19*100000000000+H19*1000000000+(I19+50)*10000000+J19*100000+(G19+50)*1000+E19*10+(4-C19) | L19: =RANK(K19,K18:K21,0)
A20: E | B20: CIV | C20: 3 | D20: =IF(AND(ISNUMBER(Grupos!D44),ISNUMBER(Grupos!E44)),IF(Grupos!D44>Grupos!E44,3,IF(Grupos!D44=Grupos!E44,1,0)),0)+IF(AND(ISNUMBER(Grupos!E45),ISNUMBER(Grupos!D45)),IF(Grupos!E45>Grupos!D45,3,IF(Grupos!E45=Grupos!D45,1,0)),0)+IF(AND(ISNUMBER(Grupos!E47),ISNUMBER(Grupos!D47)),IF(Grupos!E47>Grupos!D47,3,IF(Grupos!E47=Grupos!D47,1,0)),0) | E20: =IF(AND(ISNUMBER(Grupos!D44),ISNUMBER(Grupos!E44)),Grupos!D44,0)+IF(AND(ISNUMBER(Grupos!E45),ISNUMBER(Grupos!D45)),Grupos!E45,0)+IF(AND(ISNUMBER(Grupos!E47),ISNUMBER(Grupos!D47)),Grupos!E47,0) | F20: =IF(AND(ISNUMBER(Grupos!D44),ISNUMBER(Grupos!E44)),Grupos!E44,0)+IF(AND(ISNUMBER(Grupos!E45),ISNUMBER(Grupos!D45)),Grupos!D45,0)+IF(AND(ISNUMBER(Grupos!E47),ISNUMBER(Grupos!D47)),Grupos!D47,0) | G20: =E20-F20 | H20: =IF(AND(AND(ISNUMBER(Grupos!D44),ISNUMBER(Grupos!E44)),D21=D20),IF(Grupos!D44>Grupos!E44,3,IF(Grupos!D44=Grupos!E44,1,0)),0)+IF(AND(AND(ISNUMBER(Grupos!E45),ISNUMBER(Grupos!D45)),D18=D20),IF(Grupos!E45>Grupos!D45,3,IF(Grupos!E45=Grupos!D45,1,0)),0)+IF(AND(AND(ISNUMBER(Grupos!E47),ISNUMBER(Grupos!D47)),D19=D20),IF(Grupos!E47>Grupos!D47,3,IF(Grupos!E47=Grupos!D47,1,0)),0) | I20: =IF(AND(AND(ISNUMBER(Grupos!D44),ISNUMBER(Grupos!E44)),D21=D20),Grupos!D44-Grupos!E44,0)+IF(AND(AND(ISNUMBER(Grupos!E45),ISNUMBER(Grupos!D45)),D18=D20),Grupos!E45-Grupos!D45,0)+IF(AND(AND(ISNUMBER(Grupos!E47),ISNUMBER(Grupos!D47)),D19=D20),Grupos!E47-Grupos!D47,0) | J20: =IF(AND(AND(ISNUMBER(Grupos!D44),ISNUMBER(Grupos!E44)),D21=D20),Grupos!D44,0)+IF(AND(AND(ISNUMBER(Grupos!E45),ISNUMBER(Grupos!D45)),D18=D20),Grupos!E45,0)+IF(AND(AND(ISNUMBER(Grupos!E47),ISNUMBER(Grupos!D47)),D19=D20),Grupos!E47,0) | K20: =D20*100000000000+H20*1000000000+(I20+50)*10000000+J20*100000+(G20+50)*1000+E20*10+(4-C20) | L20: =RANK(K20,K18:K21,0)
A21: E | B21: ECU | C21: 4 | D21: =IF(AND(ISNUMBER(Grupos!E44),ISNUMBER(Grupos!D44)),IF(Grupos!E44>Grupos!D44,3,IF(Grupos!E44=Grupos!D44,1,0)),0)+IF(AND(ISNUMBER(Grupos!D46),ISNUMBER(Grupos!E46)),IF(Grupos!D46>Grupos!E46,3,IF(Grupos!D46=Grupos!E46,1,0)),0)+IF(AND(ISNUMBER(Grupos!D48),ISNUMBER(Grupos!E48)),IF(Grupos!D48>Grupos!E48,3,IF(Grupos!D48=Grupos!E48,1,0)),0) | E21: =IF(AND(ISNUMBER(Grupos!E44),ISNUMBER(Grupos!D44)),Grupos!E44,0)+IF(AND(ISNUMBER(Grupos!D46),ISNUMBER(Grupos!E46)),Grupos!D46,0)+IF(AND(ISNUMBER(Grupos!D48),ISNUMBER(Grupos!E48)),Grupos!D48,0) | F21: =IF(AND(ISNUMBER(Grupos!E44),ISNUMBER(Grupos!D44)),Grupos!D44,0)+IF(AND(ISNUMBER(Grupos!D46),ISNUMBER(Grupos!E46)),Grupos!E46,0)+IF(AND(ISNUMBER(Grupos!D48),ISNUMBER(Grupos!E48)),Grupos!E48,0) | G21: =E21-F21 | H21: =IF(AND(AND(ISNUMBER(Grupos!E44),ISNUMBER(Grupos!D44)),D20=D21),IF(Grupos!E44>Grupos!D44,3,IF(Grupos!E44=Grupos!D44,1,0)),0)+IF(AND(AND(ISNUMBER(Grupos!D46),ISNUMBER(Grupos!E46)),D19=D21),IF(Grupos!D46>Grupos!E46,3,IF(Grupos!D46=Grupos!E46,1,0)),0)+IF(AND(AND(ISNUMBER(Grupos!D48),ISNUMBER(Grupos!E48)),D18=D21),IF(Grupos!D48>Grupos!E48,3,IF(Grupos!D48=Grupos!E48,1,0)),0) | I21: =IF(AND(AND(ISNUMBER(Grupos!E44),ISNUMBER(Grupos!D44)),D20=D21),Grupos!E44-Grupos!D44,0)+IF(AND(AND(ISNUMBER(Grupos!D46),ISNUMBER(Grupos!E46)),D19=D21),Grupos!D46-Grupos!E46,0)+IF(AND(AND(ISNUMBER(Grupos!D48),ISNUMBER(Grupos!E48)),D18=D21),Grupos!D48-Grupos!E48,0) | J21: =IF(AND(AND(ISNUMBER(Grupos!E44),ISNUMBER(Grupos!D44)),D20=D21),Grupos!E44,0)+IF(AND(AND(ISNUMBER(Grupos!D46),ISNUMBER(Grupos!E46)),D19=D21),Grupos!D46,0)+IF(AND(AND(ISNUMBER(Grupos!D48),ISNUMBER(Grupos!E48)),D18=D21),Grupos!D48,0) | K21: =D21*100000000000+H21*1000000000+(I21+50)*10000000+J21*100000+(G21+50)*1000+E21*10+(4-C21) | L21: =RANK(K21,K18:K21,0)
A22: F | B22: NED | C22: 1 | D22: =IF(AND(ISNUMBER(Grupos!D52),ISNUMBER(Grupos!E52)),IF(Grupos!D52>Grupos!E52,3,IF(Grupos!D52=Grupos!E52,1,0)),0)+IF(AND(ISNUMBER(Grupos!D54),ISNUMBER(Grupos!E54)),IF(Grupos!D54>Grupos!E54,3,IF(Grupos!D54=Grupos!E54,1,0)),0)+IF(AND(ISNUMBER(Grupos!E57),ISNUMBER(Grupos!D57)),IF(Grupos!E57>Grupos!D57,3,IF(Grupos!E57=Grupos!D57,1,0)),0) | E22: =IF(AND(ISNUMBER(Grupos!D52),ISNUMBER(Grupos!E52)),Grupos!D52,0)+IF(AND(ISNUMBER(Grupos!D54),ISNUMBER(Grupos!E54)),Grupos!D54,0)+IF(AND(ISNUMBER(Grupos!E57),ISNUMBER(Grupos!D57)),Grupos!E57,0) | F22: =IF(AND(ISNUMBER(Grupos!D52),ISNUMBER(Grupos!E52)),Grupos!E52,0)+IF(AND(ISNUMBER(Grupos!D54),ISNUMBER(Grupos!E54)),Grupos!E54,0)+IF(AND(ISNUMBER(Grupos!E57),ISNUMBER(Grupos!D57)),Grupos!D57,0) | G22: =E22-F22 | H22: =IF(AND(AND(ISNUMBER(Grupos!D52),ISNUMBER(Grupos!E52)),D23=D22),IF(Grupos!D52>Grupos!E52,3,IF(Grupos!D52=Grupos!E52,1,0)),0)+IF(AND(AND(ISNUMBER(Grupos!D54),ISNUMBER(Grupos!E54)),D24=D22),IF(Grupos!D54>Grupos!E54,3,IF(Grupos!D54=Grupos!E54,1,0)),0)+IF(AND(AND(ISNUMBER(Grupos!E57),ISNUMBER(Grupos!D57)),D25=D22),IF(Grupos!E57>Grupos!D57,3,IF(Grupos!E57=Grupos!D57,1,0)),0) | I22: =IF(AND(AND(ISNUMBER(Grupos!D52),ISNUMBER(Grupos!E52)),D23=D22),Grupos!D52-Grupos!E52,0)+IF(AND(AND(ISNUMBER(Grupos!D54),ISNUMBER(Grupos!E54)),D24=D22),Grupos!D54-Grupos!E54,0)+IF(AND(AND(ISNUMBER(Grupos!E57),ISNUMBER(Grupos!D57)),D25=D22),Grupos!E57-Grupos!D57,0) | J22: =IF(AND(AND(ISNUMBER(Grupos!D52),ISNUMBER(Grupos!E52)),D23=D22),Grupos!D52,0)+IF(AND(AND(ISNUMBER(Grupos!D54),ISNUMBER(Grupos!E54)),D24=D22),Grupos!D54,0)+IF(AND(AND(ISNUMBER(Grupos!E57),ISNUMBER(Grupos!D57)),D25=D22),Grupos!E57,0) | K22: =D22*100000000000+H22*1000000000+(I22+50)*10000000+J22*100000+(G22+50)*1000+E22*10+(4-C22) | L22: =RANK(K22,K22:K25,0) | N22: =INDEX(B22:B25,MATCH(1,L22:L25,0)) | O22: =INDEX(B22:B25,MATCH(2,L22:L25,0)) | P22: =INDEX(B22:B25,MATCH(3,L22:L25,0))
A23: F | B23: JPN | C23: 2 | D23: =IF(AND(ISNUMBER(Grupos!E52),ISNUMBER(Grupos!D52)),IF(Grupos!E52>Grupos!D52,3,IF(Grupos!E52=Grupos!D52,1,0)),0)+IF(AND(ISNUMBER(Grupos!E55),ISNUMBER(Grupos!D55)),IF(Grupos!E55>Grupos!D55,3,IF(Grupos!E55=Grupos!D55,1,0)),0)+IF(AND(ISNUMBER(Grupos!D56),ISNUMBER(Grupos!E56)),IF(Grupos!D56>Grupos!E56,3,IF(Grupos!D56=Grupos!E56,1,0)),0) | E23: =IF(AND(ISNUMBER(Grupos!E52),ISNUMBER(Grupos!D52)),Grupos!E52,0)+IF(AND(ISNUMBER(Grupos!E55),ISNUMBER(Grupos!D55)),Grupos!E55,0)+IF(AND(ISNUMBER(Grupos!D56),ISNUMBER(Grupos!E56)),Grupos!D56,0) | F23: =IF(AND(ISNUMBER(Grupos!E52),ISNUMBER(Grupos!D52)),Grupos!D52,0)+IF(AND(ISNUMBER(Grupos!E55),ISNUMBER(Grupos!D55)),Grupos!D55,0)+IF(AND(ISNUMBER(Grupos!D56),ISNUMBER(Grupos!E56)),Grupos!E56,0) | G23: =E23-F23 | H23: =IF(AND(AND(ISNUMBER(Grupos!E52),ISNUMBER(Grupos!D52)),D22=D23),IF(Grupos!E52>Grupos!D52,3,IF(Grupos!E52=Grupos!D52,1,0)),0)+IF(AND(AND(ISNUMBER(Grupos!E55),ISNUMBER(Grupos!D55)),D25=D23),IF(Grupos!E55>Grupos!D55,3,IF(Grupos!E55=Grupos!D55,1,0)),0)+IF(AND(AND(ISNUMBER(Grupos!D56),ISNUMBER(Grupos!E56)),D24=D23),IF(Grupos!D56>Grupos!E56,3,IF(Grupos!D56=Grupos!E56,1,0)),0) | I23: =IF(AND(AND(ISNUMBER(Grupos!E52),ISNUMBER(Grupos!D52)),D22=D23),Grupos!E52-Grupos!D52,0)+IF(AND(AND(ISNUMBER(Grupos!E55),ISNUMBER(Grupos!D55)),D25=D23),Grupos!E55-Grupos!D55,0)+IF(AND(AND(ISNUMBER(Grupos!D56),ISNUMBER(Grupos!E56)),D24=D23),Grupos!D56-Grupos!E56,0) | J23: =IF(AND(AND(ISNUMBER(Grupos!E52),ISNUMBER(Grupos!D52)),D22=D23),Grupos!E52,0)+IF(AND(AND(ISNUMBER(Grupos!E55),ISNUMBER(Grupos!D55)),D25=D23),Grupos!E55,0)+IF(AND(AND(ISNUMBER(Grupos!D56),ISNUMBER(Grupos!E56)),D24=D23),Grupos!D56,0) | K23: =D23*100000000000+H23*1000000000+(I23+50)*10000000+J23*100000+(G23+50)*1000+E23*10+(4-C23) | L23: =RANK(K23,K22:K25,0)
A24: F | B24: SWE | C24: 3 | D24: =IF(AND(ISNUMBER(Grupos!D53),ISNUMBER(Grupos!E53)),IF(Grupos!D53>Grupos!E53,3,IF(Grupos!D53=Grupos!E53,1,0)),0)+IF(AND(ISNUMBER(Grupos!E54),ISNUMBER(Grupos!D54)),IF(Grupos!E54>Grupos!D54,3,IF(Grupos!E54=Grupos!D54,1,0)),0)+IF(AND(ISNUMBER(Grupos!E56),ISNUMBER(Grupos!D56)),IF(Grupos!E56>Grupos!D56,3,IF(Grupos!E56=Grupos!D56,1,0)),0) | E24: =IF(AND(ISNUMBER(Grupos!D53),ISNUMBER(Grupos!E53)),Grupos!D53,0)+IF(AND(ISNUMBER(Grupos!E54),ISNUMBER(Grupos!D54)),Grupos!E54,0)+IF(AND(ISNUMBER(Grupos!E56),ISNUMBER(Grupos!D56)),Grupos!E56,0) | F24: =IF(AND(ISNUMBER(Grupos!D53),ISNUMBER(Grupos!E53)),Grupos!E53,0)+IF(AND(ISNUMBER(Grupos!E54),ISNUMBER(Grupos!D54)),Grupos!D54,0)+IF(AND(ISNUMBER(Grupos!E56),ISNUMBER(Grupos!D56)),Grupos!D56,0) | G24: =E24-F24 | H24: =IF(AND(AND(ISNUMBER(Grupos!D53),ISNUMBER(Grupos!E53)),D25=D24),IF(Grupos!D53>Grupos!E53,3,IF(Grupos!D53=Grupos!E53,1,0)),0)+IF(AND(AND(ISNUMBER(Grupos!E54),ISNUMBER(Grupos!D54)),D22=D24),IF(Grupos!E54>Grupos!D54,3,IF(Grupos!E54=Grupos!D54,1,0)),0)+IF(AND(AND(ISNUMBER(Grupos!E56),ISNUMBER(Grupos!D56)),D23=D24),IF(Grupos!E56>Grupos!D56,3,IF(Grupos!E56=Grupos!D56,1,0)),0) | I24: =IF(AND(AND(ISNUMBER(Grupos!D53),ISNUMBER(Grupos!E53)),D25=D24),Grupos!D53-Grupos!E53,0)+IF(AND(AND(ISNUMBER(Grupos!E54),ISNUMBER(Grupos!D54)),D22=D24),Grupos!E54-Grupos!D54,0)+IF(AND(AND(ISNUMBER(Grupos!E56),ISNUMBER(Grupos!D56)),D23=D24),Grupos!E56-Grupos!D56,0) | J24: =IF(AND(AND(ISNUMBER(Grupos!D53),ISNUMBER(Grupos!E53)),D25=D24),Grupos!D53,0)+IF(AND(AND(ISNUMBER(Grupos!E54),ISNUMBER(Grupos!D54)),D22=D24),Grupos!E54,0)+IF(AND(AND(ISNUMBER(Grupos!E56),ISNUMBER(Grupos!D56)),D23=D24),Grupos!E56,0) | K24: =D24*100000000000+H24*1000000000+(I24+50)*10000000+J24*100000+(G24+50)*1000+E24*10+(4-C24) | L24: =RANK(K24,K22:K25,0)
A25: F | B25: TUN | C25: 4 | D25: =IF(AND(ISNUMBER(Grupos!E53),ISNUMBER(Grupos!D53)),IF(Grupos!E53>Grupos!D53,3,IF(Grupos!E53=Grupos!D53,1,0)),0)+IF(AND(ISNUMBER(Grupos!D55),ISNUMBER(Grupos!E55)),IF(Grupos!D55>Grupos!E55,3,IF(Grupos!D55=Grupos!E55,1,0)),0)+IF(AND(ISNUMBER(Grupos!D57),ISNUMBER(Grupos!E57)),IF(Grupos!D57>Grupos!E57,3,IF(Grupos!D57=Grupos!E57,1,0)),0) | E25: =IF(AND(ISNUMBER(Grupos!E53),ISNUMBER(Grupos!D53)),Grupos!E53,0)+IF(AND(ISNUMBER(Grupos!D55),ISNUMBER(Grupos!E55)),Grupos!D55,0)+IF(AND(ISNUMBER(Grupos!D57),ISNUMBER(Grupos!E57)),Grupos!D57,0) | F25: =IF(AND(ISNUMBER(Grupos!E53),ISNUMBER(Grupos!D53)),Grupos!D53,0)+IF(AND(ISNUMBER(Grupos!D55),ISNUMBER(Grupos!E55)),Grupos!E55,0)+IF(AND(ISNUMBER(Grupos!D57),ISNUMBER(Grupos!E57)),Grupos!E57,0) | G25: =E25-F25 | H25: =IF(AND(AND(ISNUMBER(Grupos!E53),ISNUMBER(Grupos!D53)),D24=D25),IF(Grupos!E53>Grupos!D53,3,IF(Grupos!E53=Grupos!D53,1,0)),0)+IF(AND(AND(ISNUMBER(Grupos!D55),ISNUMBER(Grupos!E55)),D23=D25),IF(Grupos!D55>Grupos!E55,3,IF(Grupos!D55=Grupos!E55,1,0)),0)+IF(AND(AND(ISNUMBER(Grupos!D57),ISNUMBER(Grupos!E57)),D22=D25),IF(Grupos!D57>Grupos!E57,3,IF(Grupos!D57=Grupos!E57,1,0)),0) | I25: =IF(AND(AND(ISNUMBER(Grupos!E53),ISNUMBER(Grupos!D53)),D24=D25),Grupos!E53-Grupos!D53,0)+IF(AND(AND(ISNUMBER(Grupos!D55),ISNUMBER(Grupos!E55)),D23=D25),Grupos!D55-Grupos!E55,0)+IF(AND(AND(ISNUMBER(Grupos!D57),ISNUMBER(Grupos!E57)),D22=D25),Grupos!D57-Grupos!E57,0) | J25: =IF(AND(AND(ISNUMBER(Grupos!E53),ISNUMBER(Grupos!D53)),D24=D25),Grupos!E53,0)+IF(AND(AND(ISNUMBER(Grupos!D55),ISNUMBER(Grupos!E55)),D23=D25),Grupos!D55,0)+IF(AND(AND(ISNUMBER(Grupos!D57),ISNUMBER(Grupos!E57)),D22=D25),Grupos!D57,0) | K25: =D25*100000000000+H25*1000000000+(I25+50)*10000000+J25*100000+(G25+50)*1000+E25*10+(4-C25) | L25: =RANK(K25,K22:K25,0)
A26: G | B26: BEL | C26: 1 | D26: =IF(AND(ISNUMBER(Grupos!D61),ISNUMBER(Grupos!E61)),IF(Grupos!D61>Grupos!E61,3,IF(Grupos!D61=Grupos!E61,1,0)),0)+IF(AND(ISNUMBER(Grupos!D63),ISNUMBER(Grupos!E63)),IF(Grupos!D63>Grupos!E63,3,IF(Grupos!D63=Grupos!E63,1,0)),0)+IF(AND(ISNUMBER(Grupos!E66),ISNUMBER(Grupos!D66)),IF(Grupos!E66>Grupos!D66,3,IF(Grupos!E66=Grupos!D66,1,0)),0) | E26: =IF(AND(ISNUMBER(Grupos!D61),ISNUMBER(Grupos!E61)),Grupos!D61,0)+IF(AND(ISNUMBER(Grupos!D63),ISNUMBER(Grupos!E63)),Grupos!D63,0)+IF(AND(ISNUMBER(Grupos!E66),ISNUMBER(Grupos!D66)),Grupos!E66,0) | F26: =IF(AND(ISNUMBER(Grupos!D61),ISNUMBER(Grupos!E61)),Grupos!E61,0)+IF(AND(ISNUMBER(Grupos!D63),ISNUMBER(Grupos!E63)),Grupos!E63,0)+IF(AND(ISNUMBER(Grupos!E66),ISNUMBER(Grupos!D66)),Grupos!D66,0) | G26: =E26-F26 | H26: =IF(AND(AND(ISNUMBER(Grupos!D61),ISNUMBER(Grupos!E61)),D27=D26),IF(Grupos!D61>Grupos!E61,3,IF(Grupos!D61=Grupos!E61,1,0)),0)+IF(AND(AND(ISNUMBER(Grupos!D63),ISNUMBER(Grupos!E63)),D28=D26),IF(Grupos!D63>Grupos!E63,3,IF(Grupos!D63=Grupos!E63,1,0)),0)+IF(AND(AND(ISNUMBER(Grupos!E66),ISNUMBER(Grupos!D66)),D29=D26),IF(Grupos!E66>Grupos!D66,3,IF(Grupos!E66=Grupos!D66,1,0)),0) | I26: =IF(AND(AND(ISNUMBER(Grupos!D61),ISNUMBER(Grupos!E61)),D27=D26),Grupos!D61-Grupos!E61,0)+IF(AND(AND(ISNUMBER(Grupos!D63),ISNUMBER(Grupos!E63)),D28=D26),Grupos!D63-Grupos!E63,0)+IF(AND(AND(ISNUMBER(Grupos!E66),ISNUMBER(Grupos!D66)),D29=D26),Grupos!E66-Grupos!D66,0) | J26: =IF(AND(AND(ISNUMBER(Grupos!D61),ISNUMBER(Grupos!E61)),D27=D26),Grupos!D61,0)+IF(AND(AND(ISNUMBER(Grupos!D63),ISNUMBER(Grupos!E63)),D28=D26),Grupos!D63,0)+IF(AND(AND(ISNUMBER(Grupos!E66),ISNUMBER(Grupos!D66)),D29=D26),Grupos!E66,0) | K26: =D26*100000000000+H26*1000000000+(I26+50)*10000000+J26*100000+(G26+50)*1000+E26*10+(4-C26) | L26: =RANK(K26,K26:K29,0) | N26: =INDEX(B26:B29,MATCH(1,L26:L29,0)) | O26: =INDEX(B26:B29,MATCH(2,L26:L29,0)) | P26: =INDEX(B26:B29,MATCH(3,L26:L29,0))
